2022-02-11 15:20:17,588 DEBUG urllib3.connectionpool MainThread : Starting new HTTPS connection (1): maps.googleapis.com:443
2022-02-11 15:20:18,936 DEBUG urllib3.connectionpool MainThread : https://maps.googleapis.com:443 "GET /maps/api/geocode/json?address=401+Chapel+Dr%2C+Durham%2C+NC+27705&key=AIzaSyB0b7GWpLob05JP7aVeAt9iMjY0FjDv0_o HTTP/1.1" 200 None
2022-02-11 15:20:46,960 ERROR app ThreadPoolExecutor-0_0 : Exception on /current_user [GET]
Traceback (most recent call last):
  File "/usr/local/lib/python3.8/dist-packages/sqlalchemy/engine/base.py", line 1802, in _execute_context
    self.dialect.do_execute(
  File "/usr/local/lib/python3.8/dist-packages/sqlalchemy/engine/default.py", line 732, in do_execute
    cursor.execute(statement, parameters)
psycopg2.errors.UndefinedColumn: column students.name does not exist
LINE 1: SELECT students.id AS students_id, students.name AS students...
                                           ^


The above exception was the direct cause of the following exception:

Traceback (most recent call last):
  File "/usr/local/lib/python3.8/dist-packages/flask/app.py", line 2073, in wsgi_app
    response = self.full_dispatch_request()
  File "/usr/local/lib/python3.8/dist-packages/flask/app.py", line 1518, in full_dispatch_request
    rv = self.handle_user_exception(e)
  File "/usr/local/lib/python3.8/dist-packages/flask_cors/extension.py", line 165, in wrapped_function
    return cors_after_request(app.make_response(f(*args, **kwargs)))
  File "/usr/local/lib/python3.8/dist-packages/flask/app.py", line 1516, in full_dispatch_request
    rv = self.dispatch_request()
  File "/usr/local/lib/python3.8/dist-packages/flask/app.py", line 1502, in dispatch_request
    return self.ensure_sync(self.view_functions[rule.endpoint])(**req.view_args)
  File "/usr/local/lib/python3.8/dist-packages/flask_jwt_extended/view_decorators.py", line 127, in decorator
    return current_app.ensure_sync(fn)(*args, **kwargs)
  File "/usr/local/lib/python3.8/dist-packages/flask_cors/decorator.py", line 128, in wrapped_function
    resp = make_response(f(*args, **kwargs))
  File "/app/app.py", line 76, in get_current_user
    students = Student.query.filter_by(user_id = user.id).all()
  File "/usr/local/lib/python3.8/dist-packages/sqlalchemy/orm/query.py", line 2759, in all
    return self._iter().all()
  File "/usr/local/lib/python3.8/dist-packages/sqlalchemy/orm/query.py", line 2894, in _iter
    result = self.session.execute(
  File "/usr/local/lib/python3.8/dist-packages/sqlalchemy/orm/session.py", line 1692, in execute
    result = conn._execute_20(statement, params or {}, execution_options)
  File "/usr/local/lib/python3.8/dist-packages/sqlalchemy/engine/base.py", line 1614, in _execute_20
    return meth(self, args_10style, kwargs_10style, execution_options)
  File "/usr/local/lib/python3.8/dist-packages/sqlalchemy/sql/elements.py", line 325, in _execute_on_connection
    return connection._execute_clauseelement(
  File "/usr/local/lib/python3.8/dist-packages/sqlalchemy/engine/base.py", line 1481, in _execute_clauseelement
    ret = self._execute_context(
  File "/usr/local/lib/python3.8/dist-packages/sqlalchemy/engine/base.py", line 1845, in _execute_context
    self._handle_dbapi_exception(
  File "/usr/local/lib/python3.8/dist-packages/sqlalchemy/engine/base.py", line 2026, in _handle_dbapi_exception
    util.raise_(
  File "/usr/local/lib/python3.8/dist-packages/sqlalchemy/util/compat.py", line 207, in raise_
    raise exception
  File "/usr/local/lib/python3.8/dist-packages/sqlalchemy/engine/base.py", line 1802, in _execute_context
    self.dialect.do_execute(
  File "/usr/local/lib/python3.8/dist-packages/sqlalchemy/engine/default.py", line 732, in do_execute
    cursor.execute(statement, parameters)
sqlalchemy.exc.ProgrammingError: (psycopg2.errors.UndefinedColumn) column students.name does not exist
LINE 1: SELECT students.id AS students_id, students.name AS students...
                                           ^

[SQL: SELECT students.id AS students_id, students.name AS students_name, students.student_id AS students_student_id, students.school_id AS students_school_id, students.route_id AS students_route_id, students.user_id AS students_user_id 
FROM students 
WHERE students.user_id = %(user_id_1)s]
[parameters: {'user_id_1': 1}]
(Background on this error at: https://sqlalche.me/e/14/f405)
2022-02-11 15:20:54,123 ERROR app ThreadPoolExecutor-0_0 : Exception on /current_user [GET]
Traceback (most recent call last):
  File "/usr/local/lib/python3.8/dist-packages/sqlalchemy/engine/base.py", line 1802, in _execute_context
    self.dialect.do_execute(
  File "/usr/local/lib/python3.8/dist-packages/sqlalchemy/engine/default.py", line 732, in do_execute
    cursor.execute(statement, parameters)
psycopg2.errors.UndefinedColumn: column students.name does not exist
LINE 1: SELECT students.id AS students_id, students.name AS students...
                                           ^


The above exception was the direct cause of the following exception:

Traceback (most recent call last):
  File "/usr/local/lib/python3.8/dist-packages/flask/app.py", line 2073, in wsgi_app
    response = self.full_dispatch_request()
  File "/usr/local/lib/python3.8/dist-packages/flask/app.py", line 1518, in full_dispatch_request
    rv = self.handle_user_exception(e)
  File "/usr/local/lib/python3.8/dist-packages/flask_cors/extension.py", line 165, in wrapped_function
    return cors_after_request(app.make_response(f(*args, **kwargs)))
  File "/usr/local/lib/python3.8/dist-packages/flask/app.py", line 1516, in full_dispatch_request
    rv = self.dispatch_request()
  File "/usr/local/lib/python3.8/dist-packages/flask/app.py", line 1502, in dispatch_request
    return self.ensure_sync(self.view_functions[rule.endpoint])(**req.view_args)
  File "/usr/local/lib/python3.8/dist-packages/flask_jwt_extended/view_decorators.py", line 127, in decorator
    return current_app.ensure_sync(fn)(*args, **kwargs)
  File "/usr/local/lib/python3.8/dist-packages/flask_cors/decorator.py", line 128, in wrapped_function
    resp = make_response(f(*args, **kwargs))
  File "/app/app.py", line 76, in get_current_user
    students = Student.query.filter_by(user_id = user.id).all()
  File "/usr/local/lib/python3.8/dist-packages/sqlalchemy/orm/query.py", line 2759, in all
    return self._iter().all()
  File "/usr/local/lib/python3.8/dist-packages/sqlalchemy/orm/query.py", line 2894, in _iter
    result = self.session.execute(
  File "/usr/local/lib/python3.8/dist-packages/sqlalchemy/orm/session.py", line 1692, in execute
    result = conn._execute_20(statement, params or {}, execution_options)
  File "/usr/local/lib/python3.8/dist-packages/sqlalchemy/engine/base.py", line 1614, in _execute_20
    return meth(self, args_10style, kwargs_10style, execution_options)
  File "/usr/local/lib/python3.8/dist-packages/sqlalchemy/sql/elements.py", line 325, in _execute_on_connection
    return connection._execute_clauseelement(
  File "/usr/local/lib/python3.8/dist-packages/sqlalchemy/engine/base.py", line 1481, in _execute_clauseelement
    ret = self._execute_context(
  File "/usr/local/lib/python3.8/dist-packages/sqlalchemy/engine/base.py", line 1845, in _execute_context
    self._handle_dbapi_exception(
  File "/usr/local/lib/python3.8/dist-packages/sqlalchemy/engine/base.py", line 2026, in _handle_dbapi_exception
    util.raise_(
  File "/usr/local/lib/python3.8/dist-packages/sqlalchemy/util/compat.py", line 207, in raise_
    raise exception
  File "/usr/local/lib/python3.8/dist-packages/sqlalchemy/engine/base.py", line 1802, in _execute_context
    self.dialect.do_execute(
  File "/usr/local/lib/python3.8/dist-packages/sqlalchemy/engine/default.py", line 732, in do_execute
    cursor.execute(statement, parameters)
sqlalchemy.exc.ProgrammingError: (psycopg2.errors.UndefinedColumn) column students.name does not exist
LINE 1: SELECT students.id AS students_id, students.name AS students...
                                           ^

[SQL: SELECT students.id AS students_id, students.name AS students_name, students.student_id AS students_student_id, students.school_id AS students_school_id, students.route_id AS students_route_id, students.user_id AS students_user_id 
FROM students 
WHERE students.user_id = %(user_id_1)s]
[parameters: {'user_id_1': 1}]
(Background on this error at: https://sqlalche.me/e/14/f405)
2022-02-11 15:21:54,304 DEBUG urllib3.connectionpool MainThread : Starting new HTTPS connection (1): maps.googleapis.com:443
2022-02-11 15:21:54,567 DEBUG urllib3.connectionpool MainThread : https://maps.googleapis.com:443 "GET /maps/api/geocode/json?address=401+Chapel+Dr%2C+Durham%2C+NC+27705&key=AIzaSyB0b7GWpLob05JP7aVeAt9iMjY0FjDv0_o HTTP/1.1" 200 None
2022-02-11 15:22:13,634 DEBUG urllib3.connectionpool MainThread : Starting new HTTPS connection (1): maps.googleapis.com:443
2022-02-11 15:22:14,166 DEBUG urllib3.connectionpool MainThread : https://maps.googleapis.com:443 "GET /maps/api/geocode/json?address=11256+Palos+Verdes+Court%2C+Cupertino%2C+CA+95014&key=AIzaSyB0b7GWpLob05JP7aVeAt9iMjY0FjDv0_o HTTP/1.1" 200 None
2022-02-11 15:22:14,650 DEBUG urllib3.connectionpool MainThread : https://maps.googleapis.com:443 "GET /maps/api/geocode/json?address=14524+Lodestar+Drive%2C+Grass+Valley%2C+CA+95949&key=AIzaSyB0b7GWpLob05JP7aVeAt9iMjY0FjDv0_o HTTP/1.1" 200 None
2022-02-11 15:22:15,064 DEBUG urllib3.connectionpool MainThread : https://maps.googleapis.com:443 "GET /maps/api/geocode/json?address=4329+Howe+Street%2C+Oakland%2C+CA+94611&key=AIzaSyB0b7GWpLob05JP7aVeAt9iMjY0FjDv0_o HTTP/1.1" 200 None
2022-02-11 15:22:15,504 DEBUG urllib3.connectionpool MainThread : https://maps.googleapis.com:443 "GET /maps/api/geocode/json?address=11+Eclipse+Court%2C+Alameda%2C+CA+94501&key=AIzaSyB0b7GWpLob05JP7aVeAt9iMjY0FjDv0_o HTTP/1.1" 200 None
2022-02-11 15:22:15,811 DEBUG urllib3.connectionpool MainThread : https://maps.googleapis.com:443 "GET /maps/api/geocode/json?address=6420+Via+Baron%2C+Rancho+Palos+Verdes%2C+CA+90275&key=AIzaSyB0b7GWpLob05JP7aVeAt9iMjY0FjDv0_o HTTP/1.1" 200 None
2022-02-11 15:22:16,108 DEBUG urllib3.connectionpool MainThread : https://maps.googleapis.com:443 "GET /maps/api/geocode/json?address=5472+Sunstar+Common%2C+Fremont%2C+CA+94555&key=AIzaSyB0b7GWpLob05JP7aVeAt9iMjY0FjDv0_o HTTP/1.1" 200 None
2022-02-11 15:22:16,665 DEBUG urllib3.connectionpool MainThread : https://maps.googleapis.com:443 "GET /maps/api/geocode/json?address=5397+Wentworth+Avenue%2C+Oakland%2C+CA+94601&key=AIzaSyB0b7GWpLob05JP7aVeAt9iMjY0FjDv0_o HTTP/1.1" 200 None
2022-02-11 15:22:17,181 DEBUG urllib3.connectionpool MainThread : https://maps.googleapis.com:443 "GET /maps/api/geocode/json?address=2640+8th+Avenue%2C+Oakland%2C+CA+94606&key=AIzaSyB0b7GWpLob05JP7aVeAt9iMjY0FjDv0_o HTTP/1.1" 200 None
2022-02-11 15:22:17,595 DEBUG urllib3.connectionpool MainThread : https://maps.googleapis.com:443 "GET /maps/api/geocode/json?address=1870+A+Street%2C+Oroville%2C+CA+95966&key=AIzaSyB0b7GWpLob05JP7aVeAt9iMjY0FjDv0_o HTTP/1.1" 200 None
2022-02-11 15:22:18,000 DEBUG urllib3.connectionpool MainThread : https://maps.googleapis.com:443 "GET /maps/api/geocode/json?address=775+47th+Street%2C+Oakland%2C+CA+94609&key=AIzaSyB0b7GWpLob05JP7aVeAt9iMjY0FjDv0_o HTTP/1.1" 200 None
2022-02-11 15:22:18,409 DEBUG urllib3.connectionpool MainThread : https://maps.googleapis.com:443 "GET /maps/api/geocode/json?address=51035+Conifer+Drive%2C+Soda+Springs%2C+CA+95728&key=AIzaSyB0b7GWpLob05JP7aVeAt9iMjY0FjDv0_o HTTP/1.1" 200 None
2022-02-11 15:22:18,819 DEBUG urllib3.connectionpool MainThread : https://maps.googleapis.com:443 "GET /maps/api/geocode/json?address=450+C+Street%2C+Hayward%2C+CA+94541&key=AIzaSyB0b7GWpLob05JP7aVeAt9iMjY0FjDv0_o HTTP/1.1" 200 None
2022-02-11 15:22:19,232 DEBUG urllib3.connectionpool MainThread : https://maps.googleapis.com:443 "GET /maps/api/geocode/json?address=3827+West+Chapman+Avenue%2C+Orange%2C+CA+92868&key=AIzaSyB0b7GWpLob05JP7aVeAt9iMjY0FjDv0_o HTTP/1.1" 200 None
2022-02-11 15:22:19,641 DEBUG urllib3.connectionpool MainThread : https://maps.googleapis.com:443 "GET /maps/api/geocode/json?address=37600+Sycamore+Street%2C+Newark%2C+CA+94560&key=AIzaSyB0b7GWpLob05JP7aVeAt9iMjY0FjDv0_o HTTP/1.1" 200 None
2022-02-11 15:22:20,175 DEBUG urllib3.connectionpool MainThread : https://maps.googleapis.com:443 "GET /maps/api/geocode/json?address=4920+Quonset+Drive%2C+Sacramento%2C+CA+95820&key=AIzaSyB0b7GWpLob05JP7aVeAt9iMjY0FjDv0_o HTTP/1.1" 200 None
2022-02-11 15:22:20,534 DEBUG urllib3.connectionpool MainThread : https://maps.googleapis.com:443 "GET /maps/api/geocode/json?address=4500+Margalo+Avenue%2C+Bakersfield%2C+CA+93313&key=AIzaSyB0b7GWpLob05JP7aVeAt9iMjY0FjDv0_o HTTP/1.1" 200 None
2022-02-11 15:22:21,107 DEBUG urllib3.connectionpool MainThread : https://maps.googleapis.com:443 "GET /maps/api/geocode/json?address=7800+River+Mist+Avenue%2C+Bakersfield%2C+CA+93313&key=AIzaSyB0b7GWpLob05JP7aVeAt9iMjY0FjDv0_o HTTP/1.1" 200 None
2022-02-11 15:22:21,590 DEBUG urllib3.connectionpool MainThread : https://maps.googleapis.com:443 "GET /maps/api/geocode/json?address=21950+Arnold+Center+Road%2C+Carson%2C+CA+90810&key=AIzaSyB0b7GWpLob05JP7aVeAt9iMjY0FjDv0_o HTTP/1.1" 200 None
2022-02-11 15:22:22,048 DEBUG urllib3.connectionpool MainThread : https://maps.googleapis.com:443 "GET /maps/api/geocode/json?address=10202+Vista+Drive%2C+Cupertino%2C+CA+95014&key=AIzaSyB0b7GWpLob05JP7aVeAt9iMjY0FjDv0_o HTTP/1.1" 200 None
2022-02-11 15:22:22,219 DEBUG urllib3.connectionpool MainThread : https://maps.googleapis.com:443 "GET /maps/api/geocode/json?address=5397+Wentworth+Avenue%2C+Oakland%2C+CA+94601&key=AIzaSyB0b7GWpLob05JP7aVeAt9iMjY0FjDv0_o HTTP/1.1" 200 None
2022-02-11 15:22:22,597 DEBUG urllib3.connectionpool MainThread : https://maps.googleapis.com:443 "GET /maps/api/geocode/json?address=2708+Mabel+Street%2C+Berkeley%2C+CA+94702&key=AIzaSyB0b7GWpLob05JP7aVeAt9iMjY0FjDv0_o HTTP/1.1" 200 None
2022-02-11 15:22:22,959 DEBUG urllib3.connectionpool MainThread : https://maps.googleapis.com:443 "GET /maps/api/geocode/json?address=26466+Mockingbird+Lane%2C+Hayward%2C+CA+94544&key=AIzaSyB0b7GWpLob05JP7aVeAt9iMjY0FjDv0_o HTTP/1.1" 200 None
2022-02-11 15:22:23,332 DEBUG urllib3.connectionpool MainThread : https://maps.googleapis.com:443 "GET /maps/api/geocode/json?address=2443+Sierra+Nevada+Road%2C+Mammoth+Lakes%2C+CA+93546&key=AIzaSyB0b7GWpLob05JP7aVeAt9iMjY0FjDv0_o HTTP/1.1" 200 None
2022-02-11 15:22:23,716 DEBUG urllib3.connectionpool MainThread : https://maps.googleapis.com:443 "GET /maps/api/geocode/json?address=3027+Badger+Drive%2C+Pleasanton%2C+CA+94566&key=AIzaSyB0b7GWpLob05JP7aVeAt9iMjY0FjDv0_o HTTP/1.1" 200 None
2022-02-11 15:22:24,304 DEBUG urllib3.connectionpool MainThread : https://maps.googleapis.com:443 "GET /maps/api/geocode/json?address=1+Kelton+Court%2C+Oakland%2C+CA+94611&key=AIzaSyB0b7GWpLob05JP7aVeAt9iMjY0FjDv0_o HTTP/1.1" 200 None
2022-02-11 15:22:24,645 DEBUG urllib3.connectionpool MainThread : https://maps.googleapis.com:443 "GET /maps/api/geocode/json?address=649+Praderia+Circle%2C+Fremont%2C+CA+94539&key=AIzaSyB0b7GWpLob05JP7aVeAt9iMjY0FjDv0_o HTTP/1.1" 200 None
2022-02-11 15:22:24,955 DEBUG urllib3.connectionpool MainThread : https://maps.googleapis.com:443 "GET /maps/api/geocode/json?address=680+Quintana+Road%2C+Morro+Bay%2C+CA+93442&key=AIzaSyB0b7GWpLob05JP7aVeAt9iMjY0FjDv0_o HTTP/1.1" 200 None
2022-02-11 15:22:25,380 DEBUG urllib3.connectionpool MainThread : https://maps.googleapis.com:443 "GET /maps/api/geocode/json?address=2747+68th+Avenue%2C+Oakland%2C+CA+94605&key=AIzaSyB0b7GWpLob05JP7aVeAt9iMjY0FjDv0_o HTTP/1.1" 200 None
2022-02-11 15:22:25,726 DEBUG urllib3.connectionpool MainThread : https://maps.googleapis.com:443 "GET /maps/api/geocode/json?address=1234+Carmel+Street%2C+Madera%2C+CA+93638&key=AIzaSyB0b7GWpLob05JP7aVeAt9iMjY0FjDv0_o HTTP/1.1" 200 None
2022-02-11 15:22:26,015 DEBUG urllib3.connectionpool MainThread : https://maps.googleapis.com:443 "GET /maps/api/geocode/json?address=2755+Country+Drive%2C+Fremont%2C+CA+94536&key=AIzaSyB0b7GWpLob05JP7aVeAt9iMjY0FjDv0_o HTTP/1.1" 200 None
2022-02-11 15:22:26,427 DEBUG urllib3.connectionpool MainThread : https://maps.googleapis.com:443 "GET /maps/api/geocode/json?address=36360+Beech+Place%2C+Newark%2C+CA+94560&key=AIzaSyB0b7GWpLob05JP7aVeAt9iMjY0FjDv0_o HTTP/1.1" 200 None
2022-02-11 15:22:26,726 DEBUG urllib3.connectionpool MainThread : https://maps.googleapis.com:443 "GET /maps/api/geocode/json?address=514+Flower+Lane%2C+Alameda%2C+CA+94502&key=AIzaSyB0b7GWpLob05JP7aVeAt9iMjY0FjDv0_o HTTP/1.1" 200 None
2022-02-11 15:22:27,076 DEBUG urllib3.connectionpool MainThread : https://maps.googleapis.com:443 "GET /maps/api/geocode/json?address=1357+Addison+Street%2C+Berkeley%2C+CA+94702&key=AIzaSyB0b7GWpLob05JP7aVeAt9iMjY0FjDv0_o HTTP/1.1" 200 None
2022-02-11 15:22:27,395 DEBUG urllib3.connectionpool MainThread : https://maps.googleapis.com:443 "GET /maps/api/geocode/json?address=8934+Arrowrock+Trail%2C+Smartsville%2C+CA+95977&key=AIzaSyB0b7GWpLob05JP7aVeAt9iMjY0FjDv0_o HTTP/1.1" 200 None
2022-02-11 15:22:27,757 DEBUG urllib3.connectionpool MainThread : https://maps.googleapis.com:443 "GET /maps/api/geocode/json?address=2409+Park+Street%2C+Selma%2C+CA+93662&key=AIzaSyB0b7GWpLob05JP7aVeAt9iMjY0FjDv0_o HTTP/1.1" 200 None
2022-02-11 15:22:27,858 DEBUG urllib3.connectionpool MainThread : https://maps.googleapis.com:443 "GET /maps/api/geocode/json?address=4920+Quonset+Drive%2C+Sacramento%2C+CA+95820&key=AIzaSyB0b7GWpLob05JP7aVeAt9iMjY0FjDv0_o HTTP/1.1" 200 None
2022-02-11 15:22:28,354 DEBUG urllib3.connectionpool MainThread : https://maps.googleapis.com:443 "GET /maps/api/geocode/json?address=12091+Mierkey+Road%2C+Jackson%2C+CA+95642&key=AIzaSyB0b7GWpLob05JP7aVeAt9iMjY0FjDv0_o HTTP/1.1" 200 None
2022-02-11 15:22:28,791 DEBUG urllib3.connectionpool MainThread : https://maps.googleapis.com:443 "GET /maps/api/geocode/json?address=5725+Medallion+Court%2C+Castro+Valley%2C+CA+94552&key=AIzaSyB0b7GWpLob05JP7aVeAt9iMjY0FjDv0_o HTTP/1.1" 200 None
2022-02-11 15:22:29,174 DEBUG urllib3.connectionpool MainThread : https://maps.googleapis.com:443 "GET /maps/api/geocode/json?address=894+Windmill+Park+Lane%2C+Mountain+View%2C+CA+94043&key=AIzaSyB0b7GWpLob05JP7aVeAt9iMjY0FjDv0_o HTTP/1.1" 200 None
2022-02-11 15:22:29,584 DEBUG urllib3.connectionpool MainThread : https://maps.googleapis.com:443 "GET /maps/api/geocode/json?address=1300+Lemos+Lane%2C+Fremont%2C+CA+94539&key=AIzaSyB0b7GWpLob05JP7aVeAt9iMjY0FjDv0_o HTTP/1.1" 200 None
2022-02-11 15:22:57,815 ERROR app ThreadPoolExecutor-0_0 : Exception on /student [GET]
Traceback (most recent call last):
  File "/usr/local/lib/python3.8/dist-packages/flask/app.py", line 2073, in wsgi_app
    response = self.full_dispatch_request()
  File "/usr/local/lib/python3.8/dist-packages/flask/app.py", line 1518, in full_dispatch_request
    rv = self.handle_user_exception(e)
  File "/usr/local/lib/python3.8/dist-packages/flask_cors/extension.py", line 165, in wrapped_function
    return cors_after_request(app.make_response(f(*args, **kwargs)))
  File "/usr/local/lib/python3.8/dist-packages/flask/app.py", line 1516, in full_dispatch_request
    rv = self.dispatch_request()
  File "/usr/local/lib/python3.8/dist-packages/flask/app.py", line 1502, in dispatch_request
    return self.ensure_sync(self.view_functions[rule.endpoint])(**req.view_args)
  File "/usr/local/lib/python3.8/dist-packages/flask_cors/decorator.py", line 128, in wrapped_function
    resp = make_response(f(*args, **kwargs))
  File "/app/app.py", line 43, in decorator
    return fn(*args, **kwargs)
  File "/app/app.py", line 335, in students_get
    student_filt = StudentFilter(data={'name': name_search, 'student_id': id_search, 'order_by': sort, 'page': page}).paginate()
  File "/usr/local/lib/python3.8/dist-packages/sqlalchemy_filters/filters.py", line 527, in paginate
    return Paginator(query=self.apply(), page=page, page_size=page_size)
  File "/usr/local/lib/python3.8/dist-packages/sqlalchemy_filters/filters.py", line 539, in apply
    query = self.order_by(query)
  File "/usr/local/lib/python3.8/dist-packages/sqlalchemy_filters/filters.py", line 498, in order_by
    order_by = [
  File "/usr/local/lib/python3.8/dist-packages/sqlalchemy_filters/filters.py", line 499, in <listcomp>
    self._parse_order_by(ob)
  File "/usr/local/lib/python3.8/dist-packages/sqlalchemy_filters/filters.py", line 482, in _parse_order_by
    raise OrderByException(
sqlalchemy_filters.exceptions.OrderByException: Student does not have a field called 'full_name' to use in an ORDER BY clause.
2022-02-11 15:23:01,695 ERROR app ThreadPoolExecutor-0_0 : Exception on /student [GET]
Traceback (most recent call last):
  File "/usr/local/lib/python3.8/dist-packages/flask/app.py", line 2073, in wsgi_app
    response = self.full_dispatch_request()
  File "/usr/local/lib/python3.8/dist-packages/flask/app.py", line 1518, in full_dispatch_request
    rv = self.handle_user_exception(e)
  File "/usr/local/lib/python3.8/dist-packages/flask_cors/extension.py", line 165, in wrapped_function
    return cors_after_request(app.make_response(f(*args, **kwargs)))
  File "/usr/local/lib/python3.8/dist-packages/flask/app.py", line 1516, in full_dispatch_request
    rv = self.dispatch_request()
  File "/usr/local/lib/python3.8/dist-packages/flask/app.py", line 1502, in dispatch_request
    return self.ensure_sync(self.view_functions[rule.endpoint])(**req.view_args)
  File "/usr/local/lib/python3.8/dist-packages/flask_cors/decorator.py", line 128, in wrapped_function
    resp = make_response(f(*args, **kwargs))
  File "/app/app.py", line 43, in decorator
    return fn(*args, **kwargs)
  File "/app/app.py", line 335, in students_get
    student_filt = StudentFilter(data={'name': name_search, 'student_id': id_search, 'order_by': sort, 'page': page}).paginate()
  File "/usr/local/lib/python3.8/dist-packages/sqlalchemy_filters/filters.py", line 527, in paginate
    return Paginator(query=self.apply(), page=page, page_size=page_size)
  File "/usr/local/lib/python3.8/dist-packages/sqlalchemy_filters/filters.py", line 539, in apply
    query = self.order_by(query)
  File "/usr/local/lib/python3.8/dist-packages/sqlalchemy_filters/filters.py", line 498, in order_by
    order_by = [
  File "/usr/local/lib/python3.8/dist-packages/sqlalchemy_filters/filters.py", line 499, in <listcomp>
    self._parse_order_by(ob)
  File "/usr/local/lib/python3.8/dist-packages/sqlalchemy_filters/filters.py", line 482, in _parse_order_by
    raise OrderByException(
sqlalchemy_filters.exceptions.OrderByException: Student does not have a field called 'full_name' to use in an ORDER BY clause.
2022-02-11 15:23:05,068 ERROR app ThreadPoolExecutor-0_0 : Exception on /student [GET]
Traceback (most recent call last):
  File "/usr/local/lib/python3.8/dist-packages/flask/app.py", line 2073, in wsgi_app
    response = self.full_dispatch_request()
  File "/usr/local/lib/python3.8/dist-packages/flask/app.py", line 1518, in full_dispatch_request
    rv = self.handle_user_exception(e)
  File "/usr/local/lib/python3.8/dist-packages/flask_cors/extension.py", line 165, in wrapped_function
    return cors_after_request(app.make_response(f(*args, **kwargs)))
  File "/usr/local/lib/python3.8/dist-packages/flask/app.py", line 1516, in full_dispatch_request
    rv = self.dispatch_request()
  File "/usr/local/lib/python3.8/dist-packages/flask/app.py", line 1502, in dispatch_request
    return self.ensure_sync(self.view_functions[rule.endpoint])(**req.view_args)
  File "/usr/local/lib/python3.8/dist-packages/flask_cors/decorator.py", line 128, in wrapped_function
    resp = make_response(f(*args, **kwargs))
  File "/app/app.py", line 43, in decorator
    return fn(*args, **kwargs)
  File "/app/app.py", line 335, in students_get
    student_filt = StudentFilter(data={'name': name_search, 'student_id': id_search, 'order_by': sort, 'page': page}).paginate()
  File "/usr/local/lib/python3.8/dist-packages/sqlalchemy_filters/filters.py", line 527, in paginate
    return Paginator(query=self.apply(), page=page, page_size=page_size)
  File "/usr/local/lib/python3.8/dist-packages/sqlalchemy_filters/filters.py", line 539, in apply
    query = self.order_by(query)
  File "/usr/local/lib/python3.8/dist-packages/sqlalchemy_filters/filters.py", line 498, in order_by
    order_by = [
  File "/usr/local/lib/python3.8/dist-packages/sqlalchemy_filters/filters.py", line 499, in <listcomp>
    self._parse_order_by(ob)
  File "/usr/local/lib/python3.8/dist-packages/sqlalchemy_filters/filters.py", line 482, in _parse_order_by
    raise OrderByException(
sqlalchemy_filters.exceptions.OrderByException: Student does not have a field called 'full_name' to use in an ORDER BY clause.
2022-02-11 15:25:38,358 ERROR app ThreadPoolExecutor-0_0 : Exception on /student [GET]
Traceback (most recent call last):
  File "/usr/local/lib/python3.8/dist-packages/flask/app.py", line 2073, in wsgi_app
    response = self.full_dispatch_request()
  File "/usr/local/lib/python3.8/dist-packages/flask/app.py", line 1518, in full_dispatch_request
    rv = self.handle_user_exception(e)
  File "/usr/local/lib/python3.8/dist-packages/flask_cors/extension.py", line 165, in wrapped_function
    return cors_after_request(app.make_response(f(*args, **kwargs)))
  File "/usr/local/lib/python3.8/dist-packages/flask/app.py", line 1516, in full_dispatch_request
    rv = self.dispatch_request()
  File "/usr/local/lib/python3.8/dist-packages/flask/app.py", line 1502, in dispatch_request
    return self.ensure_sync(self.view_functions[rule.endpoint])(**req.view_args)
  File "/usr/local/lib/python3.8/dist-packages/flask_cors/decorator.py", line 128, in wrapped_function
    resp = make_response(f(*args, **kwargs))
  File "/app/app.py", line 43, in decorator
    return fn(*args, **kwargs)
  File "/app/app.py", line 335, in students_get
    student_filt = StudentFilter(data={'name': name_search, 'student_id': id_search, 'order_by': sort, 'page': page}).paginate()
  File "/usr/local/lib/python3.8/dist-packages/sqlalchemy_filters/filters.py", line 527, in paginate
    return Paginator(query=self.apply(), page=page, page_size=page_size)
  File "/usr/local/lib/python3.8/dist-packages/sqlalchemy_filters/filters.py", line 539, in apply
    query = self.order_by(query)
  File "/usr/local/lib/python3.8/dist-packages/sqlalchemy_filters/filters.py", line 498, in order_by
    order_by = [
  File "/usr/local/lib/python3.8/dist-packages/sqlalchemy_filters/filters.py", line 499, in <listcomp>
    self._parse_order_by(ob)
  File "/usr/local/lib/python3.8/dist-packages/sqlalchemy_filters/filters.py", line 482, in _parse_order_by
    raise OrderByException(
sqlalchemy_filters.exceptions.OrderByException: Student does not have a field called 'full_name' to use in an ORDER BY clause.
2022-02-11 15:25:39,408 ERROR app ThreadPoolExecutor-0_0 : Exception on /student [GET]
Traceback (most recent call last):
  File "/usr/local/lib/python3.8/dist-packages/flask/app.py", line 2073, in wsgi_app
    response = self.full_dispatch_request()
  File "/usr/local/lib/python3.8/dist-packages/flask/app.py", line 1518, in full_dispatch_request
    rv = self.handle_user_exception(e)
  File "/usr/local/lib/python3.8/dist-packages/flask_cors/extension.py", line 165, in wrapped_function
    return cors_after_request(app.make_response(f(*args, **kwargs)))
  File "/usr/local/lib/python3.8/dist-packages/flask/app.py", line 1516, in full_dispatch_request
    rv = self.dispatch_request()
  File "/usr/local/lib/python3.8/dist-packages/flask/app.py", line 1502, in dispatch_request
    return self.ensure_sync(self.view_functions[rule.endpoint])(**req.view_args)
  File "/usr/local/lib/python3.8/dist-packages/flask_cors/decorator.py", line 128, in wrapped_function
    resp = make_response(f(*args, **kwargs))
  File "/app/app.py", line 43, in decorator
    return fn(*args, **kwargs)
  File "/app/app.py", line 335, in students_get
    student_filt = StudentFilter(data={'name': name_search, 'student_id': id_search, 'order_by': sort, 'page': page}).paginate()
  File "/usr/local/lib/python3.8/dist-packages/sqlalchemy_filters/filters.py", line 527, in paginate
    return Paginator(query=self.apply(), page=page, page_size=page_size)
  File "/usr/local/lib/python3.8/dist-packages/sqlalchemy_filters/filters.py", line 539, in apply
    query = self.order_by(query)
  File "/usr/local/lib/python3.8/dist-packages/sqlalchemy_filters/filters.py", line 498, in order_by
    order_by = [
  File "/usr/local/lib/python3.8/dist-packages/sqlalchemy_filters/filters.py", line 499, in <listcomp>
    self._parse_order_by(ob)
  File "/usr/local/lib/python3.8/dist-packages/sqlalchemy_filters/filters.py", line 482, in _parse_order_by
    raise OrderByException(
sqlalchemy_filters.exceptions.OrderByException: Student does not have a field called 'full_name' to use in an ORDER BY clause.
2022-02-11 15:25:49,076 ERROR app ThreadPoolExecutor-0_0 : Exception on /student [GET]
Traceback (most recent call last):
  File "/usr/local/lib/python3.8/dist-packages/flask/app.py", line 2073, in wsgi_app
    response = self.full_dispatch_request()
  File "/usr/local/lib/python3.8/dist-packages/flask/app.py", line 1518, in full_dispatch_request
    rv = self.handle_user_exception(e)
  File "/usr/local/lib/python3.8/dist-packages/flask_cors/extension.py", line 165, in wrapped_function
    return cors_after_request(app.make_response(f(*args, **kwargs)))
  File "/usr/local/lib/python3.8/dist-packages/flask/app.py", line 1516, in full_dispatch_request
    rv = self.dispatch_request()
  File "/usr/local/lib/python3.8/dist-packages/flask/app.py", line 1502, in dispatch_request
    return self.ensure_sync(self.view_functions[rule.endpoint])(**req.view_args)
  File "/usr/local/lib/python3.8/dist-packages/flask_cors/decorator.py", line 128, in wrapped_function
    resp = make_response(f(*args, **kwargs))
  File "/app/app.py", line 43, in decorator
    return fn(*args, **kwargs)
  File "/app/app.py", line 335, in students_get
    student_filt = StudentFilter(data={'name': name_search, 'student_id': id_search, 'order_by': sort, 'page': page}).paginate()
  File "/usr/local/lib/python3.8/dist-packages/sqlalchemy_filters/filters.py", line 527, in paginate
    return Paginator(query=self.apply(), page=page, page_size=page_size)
  File "/usr/local/lib/python3.8/dist-packages/sqlalchemy_filters/filters.py", line 539, in apply
    query = self.order_by(query)
  File "/usr/local/lib/python3.8/dist-packages/sqlalchemy_filters/filters.py", line 498, in order_by
    order_by = [
  File "/usr/local/lib/python3.8/dist-packages/sqlalchemy_filters/filters.py", line 499, in <listcomp>
    self._parse_order_by(ob)
  File "/usr/local/lib/python3.8/dist-packages/sqlalchemy_filters/filters.py", line 482, in _parse_order_by
    raise OrderByException(
sqlalchemy_filters.exceptions.OrderByException: Student does not have a field called 'full_name' to use in an ORDER BY clause.
2022-02-11 15:41:38,870 DEBUG root ThreadPoolExecutor-0_0 : in here10
2022-02-11 15:41:38,895 DEBUG root ThreadPoolExecutor-0_0 : in here11
2022-02-11 15:42:43,130 ERROR app ThreadPoolExecutor-0_1 : Exception on /stop/1 [GET]
Traceback (most recent call last):
  File "/usr/local/lib/python3.8/dist-packages/flask/app.py", line 2073, in wsgi_app
    response = self.full_dispatch_request()
  File "/usr/local/lib/python3.8/dist-packages/flask/app.py", line 1518, in full_dispatch_request
    rv = self.handle_user_exception(e)
  File "/usr/local/lib/python3.8/dist-packages/flask_cors/extension.py", line 165, in wrapped_function
    return cors_after_request(app.make_response(f(*args, **kwargs)))
  File "/usr/local/lib/python3.8/dist-packages/flask/app.py", line 1516, in full_dispatch_request
    rv = self.dispatch_request()
  File "/usr/local/lib/python3.8/dist-packages/flask/app.py", line 1502, in dispatch_request
    return self.ensure_sync(self.view_functions[rule.endpoint])(**req.view_args)
  File "/usr/local/lib/python3.8/dist-packages/flask_cors/decorator.py", line 128, in wrapped_function
    resp = make_response(f(*args, **kwargs))
  File "/app/app.py", line 43, in decorator
    return fn(*args, **kwargs)
  File "/app/app.py", line 763, in stops_get
    return json.dumps({'success': True, 'stop': stop.as_dict()})
  File "/app/models.py", line 130, in as_dict
    main['latitude'] = datetime.strftime("%Y-%m-%dT%H:%M:%SZ", main['latitude'])
TypeError: descriptor 'strftime' for 'datetime.date' objects doesn't apply to a 'str' object
2022-02-11 15:44:43,964 ERROR app ThreadPoolExecutor-0_0 : Exception on /stop/1 [GET]
Traceback (most recent call last):
  File "/usr/local/lib/python3.8/dist-packages/flask/app.py", line 2073, in wsgi_app
    response = self.full_dispatch_request()
  File "/usr/local/lib/python3.8/dist-packages/flask/app.py", line 1518, in full_dispatch_request
    rv = self.handle_user_exception(e)
  File "/usr/local/lib/python3.8/dist-packages/flask_cors/extension.py", line 165, in wrapped_function
    return cors_after_request(app.make_response(f(*args, **kwargs)))
  File "/usr/local/lib/python3.8/dist-packages/flask/app.py", line 1516, in full_dispatch_request
    rv = self.dispatch_request()
  File "/usr/local/lib/python3.8/dist-packages/flask/app.py", line 1502, in dispatch_request
    return self.ensure_sync(self.view_functions[rule.endpoint])(**req.view_args)
  File "/usr/local/lib/python3.8/dist-packages/flask_cors/decorator.py", line 128, in wrapped_function
    resp = make_response(f(*args, **kwargs))
  File "/app/app.py", line 43, in decorator
    return fn(*args, **kwargs)
  File "/app/app.py", line 763, in stops_get
    return json.dumps({'success': True, 'stop': stop.as_dict()})
  File "/app/models.py", line 130, in as_dict
    main['pickup_time'] = datetime.strftime("%Y-%m-%dT%H:%M:%SZ", main['pickup_time'])
TypeError: descriptor 'strftime' for 'datetime.date' objects doesn't apply to a 'str' object
2022-02-11 15:45:18,966 ERROR app ThreadPoolExecutor-0_0 : Exception on /stop/1 [GET]
Traceback (most recent call last):
  File "/usr/local/lib/python3.8/dist-packages/flask/app.py", line 2073, in wsgi_app
    response = self.full_dispatch_request()
  File "/usr/local/lib/python3.8/dist-packages/flask/app.py", line 1518, in full_dispatch_request
    rv = self.handle_user_exception(e)
  File "/usr/local/lib/python3.8/dist-packages/flask_cors/extension.py", line 165, in wrapped_function
    return cors_after_request(app.make_response(f(*args, **kwargs)))
  File "/usr/local/lib/python3.8/dist-packages/flask/app.py", line 1516, in full_dispatch_request
    rv = self.dispatch_request()
  File "/usr/local/lib/python3.8/dist-packages/flask/app.py", line 1502, in dispatch_request
    return self.ensure_sync(self.view_functions[rule.endpoint])(**req.view_args)
  File "/usr/local/lib/python3.8/dist-packages/flask_cors/decorator.py", line 128, in wrapped_function
    resp = make_response(f(*args, **kwargs))
  File "/app/app.py", line 43, in decorator
    return fn(*args, **kwargs)
  File "/app/app.py", line 763, in stops_get
    return json.dumps({'success': True, 'stop': stop.as_dict()})
  File "/app/models.py", line 130, in as_dict
    main['pickup_time'] = datetime.strftime("%Y-%m-%dT%H:%M:%SZ", self.pickup_time)
TypeError: descriptor 'strftime' for 'datetime.date' objects doesn't apply to a 'str' object
2022-02-11 15:46:37,175 ERROR app ThreadPoolExecutor-0_0 : Exception on /stop/1 [GET]
Traceback (most recent call last):
  File "/usr/local/lib/python3.8/dist-packages/flask/app.py", line 2073, in wsgi_app
    response = self.full_dispatch_request()
  File "/usr/local/lib/python3.8/dist-packages/flask/app.py", line 1518, in full_dispatch_request
    rv = self.handle_user_exception(e)
  File "/usr/local/lib/python3.8/dist-packages/flask_cors/extension.py", line 165, in wrapped_function
    return cors_after_request(app.make_response(f(*args, **kwargs)))
  File "/usr/local/lib/python3.8/dist-packages/flask/app.py", line 1516, in full_dispatch_request
    rv = self.dispatch_request()
  File "/usr/local/lib/python3.8/dist-packages/flask/app.py", line 1502, in dispatch_request
    return self.ensure_sync(self.view_functions[rule.endpoint])(**req.view_args)
  File "/usr/local/lib/python3.8/dist-packages/flask_cors/decorator.py", line 128, in wrapped_function
    resp = make_response(f(*args, **kwargs))
  File "/app/app.py", line 43, in decorator
    return fn(*args, **kwargs)
  File "/app/app.py", line 763, in stops_get
    return json.dumps({'success': True, 'stop': stop.as_dict()})
  File "/app/models.py", line 130, in as_dict
    logging.debug(type(self.pickup_time))
NameError: name 'logging' is not defined
2022-02-11 15:47:23,696 DEBUG root ThreadPoolExecutor-0_0 : <class 'NoneType'>
2022-02-11 15:47:23,699 ERROR app ThreadPoolExecutor-0_0 : Exception on /stop/1 [GET]
Traceback (most recent call last):
  File "/usr/local/lib/python3.8/dist-packages/flask/app.py", line 2073, in wsgi_app
    response = self.full_dispatch_request()
  File "/usr/local/lib/python3.8/dist-packages/flask/app.py", line 1518, in full_dispatch_request
    rv = self.handle_user_exception(e)
  File "/usr/local/lib/python3.8/dist-packages/flask_cors/extension.py", line 165, in wrapped_function
    return cors_after_request(app.make_response(f(*args, **kwargs)))
  File "/usr/local/lib/python3.8/dist-packages/flask/app.py", line 1516, in full_dispatch_request
    rv = self.dispatch_request()
  File "/usr/local/lib/python3.8/dist-packages/flask/app.py", line 1502, in dispatch_request
    return self.ensure_sync(self.view_functions[rule.endpoint])(**req.view_args)
  File "/usr/local/lib/python3.8/dist-packages/flask_cors/decorator.py", line 128, in wrapped_function
    resp = make_response(f(*args, **kwargs))
  File "/app/app.py", line 43, in decorator
    return fn(*args, **kwargs)
  File "/app/app.py", line 763, in stops_get
    return json.dumps({'success': True, 'stop': stop.as_dict()})
  File "/app/models.py", line 135, in as_dict
    main['pickup_time'] = datetime.strftime("%Y-%m-%dT%H:%M:%SZ", self.pickup_time)
TypeError: descriptor 'strftime' for 'datetime.date' objects doesn't apply to a 'str' object
2022-02-11 15:49:20,270 DEBUG root ThreadPoolExecutor-0_0 : <class 'datetime.time'>
2022-02-11 15:49:20,272 ERROR app ThreadPoolExecutor-0_0 : Exception on /stop/3 [GET]
Traceback (most recent call last):
  File "/usr/local/lib/python3.8/dist-packages/flask/app.py", line 2073, in wsgi_app
    response = self.full_dispatch_request()
  File "/usr/local/lib/python3.8/dist-packages/flask/app.py", line 1518, in full_dispatch_request
    rv = self.handle_user_exception(e)
  File "/usr/local/lib/python3.8/dist-packages/flask_cors/extension.py", line 165, in wrapped_function
    return cors_after_request(app.make_response(f(*args, **kwargs)))
  File "/usr/local/lib/python3.8/dist-packages/flask/app.py", line 1516, in full_dispatch_request
    rv = self.dispatch_request()
  File "/usr/local/lib/python3.8/dist-packages/flask/app.py", line 1502, in dispatch_request
    return self.ensure_sync(self.view_functions[rule.endpoint])(**req.view_args)
  File "/usr/local/lib/python3.8/dist-packages/flask_cors/decorator.py", line 128, in wrapped_function
    resp = make_response(f(*args, **kwargs))
  File "/app/app.py", line 43, in decorator
    return fn(*args, **kwargs)
  File "/app/app.py", line 763, in stops_get
    return json.dumps({'success': True, 'stop': stop.as_dict()})
  File "/app/models.py", line 135, in as_dict
    main['pickup_time'] = datetime.strftime("%Y-%m-%dT%H:%M:%SZ", self.pickup_time)
TypeError: descriptor 'strftime' for 'datetime.date' objects doesn't apply to a 'str' object
2022-02-11 15:51:19,889 DEBUG root ThreadPoolExecutor-0_0 : <class 'datetime.time'>
2022-02-15 20:14:13,766 ERROR app ThreadPoolExecutor-0_0 : Exception on /get_time_dist [POST]
Traceback (most recent call last):
  File "/usr/local/lib/python3.8/dist-packages/flask/app.py", line 2073, in wsgi_app
    response = self.full_dispatch_request()
  File "/usr/local/lib/python3.8/dist-packages/flask/app.py", line 1518, in full_dispatch_request
    rv = self.handle_user_exception(e)
  File "/usr/local/lib/python3.8/dist-packages/flask_cors/extension.py", line 165, in wrapped_function
    return cors_after_request(app.make_response(f(*args, **kwargs)))
  File "/usr/local/lib/python3.8/dist-packages/flask/app.py", line 1516, in full_dispatch_request
    rv = self.dispatch_request()
  File "/usr/local/lib/python3.8/dist-packages/flask/app.py", line 1502, in dispatch_request
    return self.ensure_sync(self.view_functions[rule.endpoint])(**req.view_args)
  File "/usr/local/lib/python3.8/dist-packages/flask_cors/decorator.py", line 128, in wrapped_function
    resp = make_response(f(*args, **kwargs))
  File "/app/app.py", line 76, in get_time_dist
    get_time_and_dist(stops)
  File "/app/app.py", line 872, in get_time_and_dist
    origins.append(str(stop.lat) + ' ' + str(stop.long))
AttributeError: 'dict' object has no attribute 'lat'
2022-02-15 20:21:34,306 ERROR app ThreadPoolExecutor-0_0 : Exception on /route [GET]
Traceback (most recent call last):
  File "/usr/local/lib/python3.8/dist-packages/sqlalchemy/engine/base.py", line 1802, in _execute_context
    self.dialect.do_execute(
  File "/usr/local/lib/python3.8/dist-packages/sqlalchemy/engine/default.py", line 732, in do_execute
    cursor.execute(statement, parameters)
psycopg2.errors.UndefinedColumn: column stops.index does not exist
LINE 1: ...tops_longitude, stops.latitude AS stops_latitude, stops.inde...
                                                             ^


The above exception was the direct cause of the following exception:

Traceback (most recent call last):
  File "/usr/local/lib/python3.8/dist-packages/flask/app.py", line 2073, in wsgi_app
    response = self.full_dispatch_request()
  File "/usr/local/lib/python3.8/dist-packages/flask/app.py", line 1518, in full_dispatch_request
    rv = self.handle_user_exception(e)
  File "/usr/local/lib/python3.8/dist-packages/flask_cors/extension.py", line 165, in wrapped_function
    return cors_after_request(app.make_response(f(*args, **kwargs)))
  File "/usr/local/lib/python3.8/dist-packages/flask/app.py", line 1516, in full_dispatch_request
    rv = self.dispatch_request()
  File "/usr/local/lib/python3.8/dist-packages/flask/app.py", line 1502, in dispatch_request
    return self.ensure_sync(self.view_functions[rule.endpoint])(**req.view_args)
  File "/usr/local/lib/python3.8/dist-packages/flask_cors/decorator.py", line 128, in wrapped_function
    resp = make_response(f(*args, **kwargs))
  File "/app/app.py", line 46, in decorator
    return fn(*args, **kwargs)
  File "/app/app.py", line 668, in routes_get
    all_routes.append(route.as_dict())
  File "/app/models.py", line 93, in as_dict
    stops = [stop.id for stop in self.stops]
  File "/usr/local/lib/python3.8/dist-packages/sqlalchemy/orm/attributes.py", line 481, in __get__
    return self.impl.get(state, dict_)
  File "/usr/local/lib/python3.8/dist-packages/sqlalchemy/orm/attributes.py", line 941, in get
    value = self._fire_loader_callables(state, key, passive)
  File "/usr/local/lib/python3.8/dist-packages/sqlalchemy/orm/attributes.py", line 977, in _fire_loader_callables
    return self.callable_(state, passive)
  File "/usr/local/lib/python3.8/dist-packages/sqlalchemy/orm/strategies.py", line 911, in _load_for_state
    return self._emit_lazyload(
  File "/usr/local/lib/python3.8/dist-packages/sqlalchemy/orm/strategies.py", line 1047, in _emit_lazyload
    result = session.execute(
  File "/usr/local/lib/python3.8/dist-packages/sqlalchemy/orm/session.py", line 1692, in execute
    result = conn._execute_20(statement, params or {}, execution_options)
  File "/usr/local/lib/python3.8/dist-packages/sqlalchemy/engine/base.py", line 1614, in _execute_20
    return meth(self, args_10style, kwargs_10style, execution_options)
  File "/usr/local/lib/python3.8/dist-packages/sqlalchemy/sql/elements.py", line 325, in _execute_on_connection
    return connection._execute_clauseelement(
  File "/usr/local/lib/python3.8/dist-packages/sqlalchemy/engine/base.py", line 1481, in _execute_clauseelement
    ret = self._execute_context(
  File "/usr/local/lib/python3.8/dist-packages/sqlalchemy/engine/base.py", line 1845, in _execute_context
    self._handle_dbapi_exception(
  File "/usr/local/lib/python3.8/dist-packages/sqlalchemy/engine/base.py", line 2026, in _handle_dbapi_exception
    util.raise_(
  File "/usr/local/lib/python3.8/dist-packages/sqlalchemy/util/compat.py", line 207, in raise_
    raise exception
  File "/usr/local/lib/python3.8/dist-packages/sqlalchemy/engine/base.py", line 1802, in _execute_context
    self.dialect.do_execute(
  File "/usr/local/lib/python3.8/dist-packages/sqlalchemy/engine/default.py", line 732, in do_execute
    cursor.execute(statement, parameters)
sqlalchemy.exc.ProgrammingError: (psycopg2.errors.UndefinedColumn) column stops.index does not exist
LINE 1: ...tops_longitude, stops.latitude AS stops_latitude, stops.inde...
                                                             ^

[SQL: SELECT stops.id AS stops_id, stops.name AS stops_name, stops.location AS stops_location, stops.pickup_time AS stops_pickup_time, stops.dropoff_time AS stops_dropoff_time, stops.route_id AS stops_route_id, stops.longitude AS stops_longitude, stops.latitude AS stops_latitude, stops.index AS stops_index 
FROM stops 
WHERE %(param_1)s = stops.route_id]
[parameters: {'param_1': 1}]
(Background on this error at: https://sqlalche.me/e/14/f405)
2022-02-15 20:21:36,009 ERROR app ThreadPoolExecutor-0_0 : Exception on /school [GET]
Traceback (most recent call last):
  File "/usr/local/lib/python3.8/dist-packages/sqlalchemy/engine/base.py", line 1802, in _execute_context
    self.dialect.do_execute(
  File "/usr/local/lib/python3.8/dist-packages/sqlalchemy/engine/default.py", line 732, in do_execute
    cursor.execute(statement, parameters)
psycopg2.errors.UndefinedColumn: column stops.index does not exist
LINE 1: ...tops_longitude, stops.latitude AS stops_latitude, stops.inde...
                                                             ^


The above exception was the direct cause of the following exception:

Traceback (most recent call last):
  File "/usr/local/lib/python3.8/dist-packages/flask/app.py", line 2073, in wsgi_app
    response = self.full_dispatch_request()
  File "/usr/local/lib/python3.8/dist-packages/flask/app.py", line 1518, in full_dispatch_request
    rv = self.handle_user_exception(e)
  File "/usr/local/lib/python3.8/dist-packages/flask_cors/extension.py", line 165, in wrapped_function
    return cors_after_request(app.make_response(f(*args, **kwargs)))
  File "/usr/local/lib/python3.8/dist-packages/flask/app.py", line 1516, in full_dispatch_request
    rv = self.dispatch_request()
  File "/usr/local/lib/python3.8/dist-packages/flask/app.py", line 1502, in dispatch_request
    return self.ensure_sync(self.view_functions[rule.endpoint])(**req.view_args)
  File "/usr/local/lib/python3.8/dist-packages/flask_cors/decorator.py", line 128, in wrapped_function
    resp = make_response(f(*args, **kwargs))
  File "/app/app.py", line 46, in decorator
    return fn(*args, **kwargs)
  File "/app/app.py", line 522, in schools_get
    all_schools.append(school.as_dict())
  File "/app/models.py", line 56, in as_dict
    routes = [route.as_dict() for route in self.routes]
  File "/app/models.py", line 56, in <listcomp>
    routes = [route.as_dict() for route in self.routes]
  File "/app/models.py", line 93, in as_dict
    stops = [stop.id for stop in self.stops]
  File "/usr/local/lib/python3.8/dist-packages/sqlalchemy/orm/attributes.py", line 481, in __get__
    return self.impl.get(state, dict_)
  File "/usr/local/lib/python3.8/dist-packages/sqlalchemy/orm/attributes.py", line 941, in get
    value = self._fire_loader_callables(state, key, passive)
  File "/usr/local/lib/python3.8/dist-packages/sqlalchemy/orm/attributes.py", line 977, in _fire_loader_callables
    return self.callable_(state, passive)
  File "/usr/local/lib/python3.8/dist-packages/sqlalchemy/orm/strategies.py", line 911, in _load_for_state
    return self._emit_lazyload(
  File "/usr/local/lib/python3.8/dist-packages/sqlalchemy/orm/strategies.py", line 1047, in _emit_lazyload
    result = session.execute(
  File "/usr/local/lib/python3.8/dist-packages/sqlalchemy/orm/session.py", line 1692, in execute
    result = conn._execute_20(statement, params or {}, execution_options)
  File "/usr/local/lib/python3.8/dist-packages/sqlalchemy/engine/base.py", line 1614, in _execute_20
    return meth(self, args_10style, kwargs_10style, execution_options)
  File "/usr/local/lib/python3.8/dist-packages/sqlalchemy/sql/elements.py", line 325, in _execute_on_connection
    return connection._execute_clauseelement(
  File "/usr/local/lib/python3.8/dist-packages/sqlalchemy/engine/base.py", line 1481, in _execute_clauseelement
    ret = self._execute_context(
  File "/usr/local/lib/python3.8/dist-packages/sqlalchemy/engine/base.py", line 1845, in _execute_context
    self._handle_dbapi_exception(
  File "/usr/local/lib/python3.8/dist-packages/sqlalchemy/engine/base.py", line 2026, in _handle_dbapi_exception
    util.raise_(
  File "/usr/local/lib/python3.8/dist-packages/sqlalchemy/util/compat.py", line 207, in raise_
    raise exception
  File "/usr/local/lib/python3.8/dist-packages/sqlalchemy/engine/base.py", line 1802, in _execute_context
    self.dialect.do_execute(
  File "/usr/local/lib/python3.8/dist-packages/sqlalchemy/engine/default.py", line 732, in do_execute
    cursor.execute(statement, parameters)
sqlalchemy.exc.ProgrammingError: (psycopg2.errors.UndefinedColumn) column stops.index does not exist
LINE 1: ...tops_longitude, stops.latitude AS stops_latitude, stops.inde...
                                                             ^

[SQL: SELECT stops.id AS stops_id, stops.name AS stops_name, stops.location AS stops_location, stops.pickup_time AS stops_pickup_time, stops.dropoff_time AS stops_dropoff_time, stops.route_id AS stops_route_id, stops.longitude AS stops_longitude, stops.latitude AS stops_latitude, stops.index AS stops_index 
FROM stops 
WHERE %(param_1)s = stops.route_id]
[parameters: {'param_1': 1}]
(Background on this error at: https://sqlalche.me/e/14/f405)
2022-02-15 20:21:39,305 ERROR app ThreadPoolExecutor-0_0 : Exception on /school/14 [GET]
Traceback (most recent call last):
  File "/usr/local/lib/python3.8/dist-packages/flask/app.py", line 2073, in wsgi_app
    response = self.full_dispatch_request()
  File "/usr/local/lib/python3.8/dist-packages/flask/app.py", line 1518, in full_dispatch_request
    rv = self.handle_user_exception(e)
  File "/usr/local/lib/python3.8/dist-packages/flask_cors/extension.py", line 165, in wrapped_function
    return cors_after_request(app.make_response(f(*args, **kwargs)))
  File "/usr/local/lib/python3.8/dist-packages/flask/app.py", line 1516, in full_dispatch_request
    rv = self.dispatch_request()
  File "/usr/local/lib/python3.8/dist-packages/flask/app.py", line 1502, in dispatch_request
    return self.ensure_sync(self.view_functions[rule.endpoint])(**req.view_args)
  File "/usr/local/lib/python3.8/dist-packages/flask_cors/decorator.py", line 128, in wrapped_function
    resp = make_response(f(*args, **kwargs))
  File "/app/app.py", line 46, in decorator
    return fn(*args, **kwargs)
  File "/app/app.py", line 518, in schools_get
    return json.dumps({'success': True, 'school': school.as_dict()})
  File "/app/models.py", line 60, in as_dict
    main['arrival_time'] = self.arrival_time.isoformat()
AttributeError: 'NoneType' object has no attribute 'isoformat'
2022-02-15 20:21:57,385 ERROR app ThreadPoolExecutor-0_0 : Exception on /school/14 [GET]
Traceback (most recent call last):
  File "/usr/local/lib/python3.8/dist-packages/flask/app.py", line 2073, in wsgi_app
    response = self.full_dispatch_request()
  File "/usr/local/lib/python3.8/dist-packages/flask/app.py", line 1518, in full_dispatch_request
    rv = self.handle_user_exception(e)
  File "/usr/local/lib/python3.8/dist-packages/flask_cors/extension.py", line 165, in wrapped_function
    return cors_after_request(app.make_response(f(*args, **kwargs)))
  File "/usr/local/lib/python3.8/dist-packages/flask/app.py", line 1516, in full_dispatch_request
    rv = self.dispatch_request()
  File "/usr/local/lib/python3.8/dist-packages/flask/app.py", line 1502, in dispatch_request
    return self.ensure_sync(self.view_functions[rule.endpoint])(**req.view_args)
  File "/usr/local/lib/python3.8/dist-packages/flask_cors/decorator.py", line 128, in wrapped_function
    resp = make_response(f(*args, **kwargs))
  File "/app/app.py", line 46, in decorator
    return fn(*args, **kwargs)
  File "/app/app.py", line 518, in schools_get
    return json.dumps({'success': True, 'school': school.as_dict()})
  File "/app/models.py", line 60, in as_dict
    main['arrival_time'] = self.arrival_time.isoformat()
AttributeError: 'NoneType' object has no attribute 'isoformat'
2022-02-15 20:23:13,739 DEBUG urllib3.connectionpool ThreadPoolExecutor-0_0 : Starting new HTTPS connection (1): maps.googleapis.com:443
2022-02-15 20:23:14,748 DEBUG urllib3.connectionpool ThreadPoolExecutor-0_0 : https://maps.googleapis.com:443 "GET /maps/api/distancematrix/json?destinations=40.7779857+-73.9558288%7C40.79042+-73.97163&origins=40.78457+-73.95774%7C40.7779857+-73.9558288&key=AIzaSyB0b7GWpLob05JP7aVeAt9iMjY0FjDv0_o HTTP/1.1" 200 None
2022-02-15 20:23:14,761 DEBUG root ThreadPoolExecutor-0_0 : {'destination_addresses': ['155b E 84th St, New York, NY 10028, USA', '147 W 91st St, New York, NY 10024, USA'], 'origin_addresses': ['1 E 91st St, New York, NY 10128, USA', '155b E 84th St, New York, NY 10028, USA'], 'rows': [{'elements': [{'distance': {'text': '1.1 km', 'value': 1136}, 'duration': {'text': '5 mins', 'value': 323}, 'status': 'OK'}, {'distance': {'text': '2.3 km', 'value': 2279}, 'duration': {'text': '7 mins', 'value': 427}, 'status': 'OK'}]}, {'elements': [{'distance': {'text': '1 m', 'value': 0}, 'duration': {'text': '1 min', 'value': 0}, 'status': 'OK'}, {'distance': {'text': '2.5 km', 'value': 2545}, 'duration': {'text': '11 mins', 'value': 631}, 'status': 'OK'}]}], 'status': 'OK'}
2022-02-15 20:27:17,143 DEBUG urllib3.connectionpool ThreadPoolExecutor-0_0 : Starting new HTTPS connection (1): maps.googleapis.com:443
2022-02-15 20:27:17,376 DEBUG urllib3.connectionpool ThreadPoolExecutor-0_0 : https://maps.googleapis.com:443 "GET /maps/api/distancematrix/json?destinations=40.7779857+-73.9558288&origins=40.78457+-73.95774&key=AIzaSyB0b7GWpLob05JP7aVeAt9iMjY0FjDv0_o HTTP/1.1" 200 None
2022-02-15 20:27:17,470 DEBUG urllib3.connectionpool ThreadPoolExecutor-0_0 : https://maps.googleapis.com:443 "GET /maps/api/distancematrix/json?destinations=40.79042+-73.97163&origins=40.7779857+-73.9558288&key=AIzaSyB0b7GWpLob05JP7aVeAt9iMjY0FjDv0_o HTTP/1.1" 200 None
2022-02-15 20:27:17,483 DEBUG root ThreadPoolExecutor-0_0 : ['11 mins']
2022-02-15 20:28:24,117 DEBUG urllib3.connectionpool ThreadPoolExecutor-0_0 : Starting new HTTPS connection (1): maps.googleapis.com:443
2022-02-15 20:28:24,596 DEBUG urllib3.connectionpool ThreadPoolExecutor-0_0 : https://maps.googleapis.com:443 "GET /maps/api/distancematrix/json?destinations=40.7779857+-73.9558288&origins=40.78457+-73.95774&key=AIzaSyB0b7GWpLob05JP7aVeAt9iMjY0FjDv0_o HTTP/1.1" 200 None
2022-02-15 20:28:24,862 DEBUG urllib3.connectionpool ThreadPoolExecutor-0_0 : https://maps.googleapis.com:443 "GET /maps/api/distancematrix/json?destinations=40.79042+-73.97163&origins=40.7779857+-73.9558288&key=AIzaSyB0b7GWpLob05JP7aVeAt9iMjY0FjDv0_o HTTP/1.1" 200 None
2022-02-15 20:28:24,866 DEBUG root ThreadPoolExecutor-0_0 : ['5 mins', '11 mins']
2022-02-15 20:29:27,617 DEBUG urllib3.connectionpool ThreadPoolExecutor-0_0 : Starting new HTTPS connection (1): maps.googleapis.com:443
2022-02-15 20:29:27,869 DEBUG urllib3.connectionpool ThreadPoolExecutor-0_0 : https://maps.googleapis.com:443 "GET /maps/api/distancematrix/json?destinations=40.7779857+-73.9558288&origins=40.78457+-73.95774&key=AIzaSyB0b7GWpLob05JP7aVeAt9iMjY0FjDv0_o HTTP/1.1" 200 None
2022-02-15 20:29:28,191 DEBUG urllib3.connectionpool ThreadPoolExecutor-0_0 : https://maps.googleapis.com:443 "GET /maps/api/distancematrix/json?destinations=40.79042+-73.97163&origins=40.7779857+-73.9558288&key=AIzaSyB0b7GWpLob05JP7aVeAt9iMjY0FjDv0_o HTTP/1.1" 200 None
2022-02-15 20:29:28,195 DEBUG root ThreadPoolExecutor-0_0 : [{'destination_addresses': ['155b E 84th St, New York, NY 10028, USA'], 'origin_addresses': ['1 E 91st St, New York, NY 10128, USA'], 'rows': [{'elements': [{'distance': {'text': '1.1 km', 'value': 1136}, 'duration': {'text': '5 mins', 'value': 323}, 'status': 'OK'}]}], 'status': 'OK'}, {'destination_addresses': ['147 W 91st St, New York, NY 10024, USA'], 'origin_addresses': ['155b E 84th St, New York, NY 10028, USA'], 'rows': [{'elements': [{'distance': {'text': '2.5 km', 'value': 2545}, 'duration': {'text': '11 mins', 'value': 631}, 'status': 'OK'}]}], 'status': 'OK'}]
2022-02-16 04:25:21,422 DEBUG urllib3.connectionpool ThreadPoolExecutor-0_0 : Starting new HTTPS connection (1): maps.googleapis.com:443
2022-02-16 04:25:22,478 DEBUG urllib3.connectionpool ThreadPoolExecutor-0_0 : https://maps.googleapis.com:443 "GET /maps/api/distancematrix/json?destinations=40.7779857+-73.9558288&origins=40.78457+-73.95774&key=AIzaSyB0b7GWpLob05JP7aVeAt9iMjY0FjDv0_o HTTP/1.1" 200 None
2022-02-16 04:25:22,679 DEBUG urllib3.connectionpool ThreadPoolExecutor-0_0 : https://maps.googleapis.com:443 "GET /maps/api/distancematrix/json?destinations=40.79042+-73.97163&origins=40.7779857+-73.9558288&key=AIzaSyB0b7GWpLob05JP7aVeAt9iMjY0FjDv0_o HTTP/1.1" 200 None
2022-02-16 04:25:22,683 DEBUG root ThreadPoolExecutor-0_0 : [323, 631]
2022-02-16 04:26:25,920 ERROR app ThreadPoolExecutor-0_0 : Exception on /get_time_dist [POST]
Traceback (most recent call last):
  File "/usr/local/lib/python3.8/dist-packages/flask/app.py", line 2073, in wsgi_app
    response = self.full_dispatch_request()
  File "/usr/local/lib/python3.8/dist-packages/flask/app.py", line 1518, in full_dispatch_request
    rv = self.handle_user_exception(e)
  File "/usr/local/lib/python3.8/dist-packages/flask_cors/extension.py", line 165, in wrapped_function
    return cors_after_request(app.make_response(f(*args, **kwargs)))
  File "/usr/local/lib/python3.8/dist-packages/flask/app.py", line 1516, in full_dispatch_request
    rv = self.dispatch_request()
  File "/usr/local/lib/python3.8/dist-packages/flask/app.py", line 1502, in dispatch_request
    return self.ensure_sync(self.view_functions[rule.endpoint])(**req.view_args)
  File "/usr/local/lib/python3.8/dist-packages/flask_cors/decorator.py", line 128, in wrapped_function
    resp = make_response(f(*args, **kwargs))
  File "/app/app.py", line 82, in get_time_dist
    get_time_and_dist(stops, departure_time, arrival_time)
TypeError: get_time_and_dist() missing 2 required positional arguments: 'school_lat' and 'school_long'
2022-02-16 04:27:49,276 DEBUG urllib3.connectionpool ThreadPoolExecutor-0_0 : Starting new HTTPS connection (1): maps.googleapis.com:443
2022-02-16 04:27:49,646 DEBUG urllib3.connectionpool ThreadPoolExecutor-0_0 : https://maps.googleapis.com:443 "GET /maps/api/distancematrix/json?destinations=40.78457+-73.95774&origins=40.78174+-73.95491&key=AIzaSyB0b7GWpLob05JP7aVeAt9iMjY0FjDv0_o HTTP/1.1" 200 None
2022-02-16 04:27:49,796 DEBUG urllib3.connectionpool ThreadPoolExecutor-0_0 : https://maps.googleapis.com:443 "GET /maps/api/distancematrix/json?destinations=40.7779857+-73.9558288&origins=40.78457+-73.95774&key=AIzaSyB0b7GWpLob05JP7aVeAt9iMjY0FjDv0_o HTTP/1.1" 200 None
2022-02-16 04:27:49,910 DEBUG urllib3.connectionpool ThreadPoolExecutor-0_0 : https://maps.googleapis.com:443 "GET /maps/api/distancematrix/json?destinations=40.79042+-73.97163&origins=40.7779857+-73.9558288&key=AIzaSyB0b7GWpLob05JP7aVeAt9iMjY0FjDv0_o HTTP/1.1" 200 None
2022-02-16 04:27:49,914 DEBUG root ThreadPoolExecutor-0_0 : [185, 323, 631]
2022-02-16 04:27:49,915 ERROR app ThreadPoolExecutor-0_0 : Exception on /get_time_dist [POST]
Traceback (most recent call last):
  File "/usr/local/lib/python3.8/dist-packages/flask/app.py", line 2073, in wsgi_app
    response = self.full_dispatch_request()
  File "/usr/local/lib/python3.8/dist-packages/flask/app.py", line 1518, in full_dispatch_request
    rv = self.handle_user_exception(e)
  File "/usr/local/lib/python3.8/dist-packages/flask_cors/extension.py", line 165, in wrapped_function
    return cors_after_request(app.make_response(f(*args, **kwargs)))
  File "/usr/local/lib/python3.8/dist-packages/flask/app.py", line 1516, in full_dispatch_request
    rv = self.dispatch_request()
  File "/usr/local/lib/python3.8/dist-packages/flask/app.py", line 1502, in dispatch_request
    return self.ensure_sync(self.view_functions[rule.endpoint])(**req.view_args)
  File "/usr/local/lib/python3.8/dist-packages/flask_cors/decorator.py", line 128, in wrapped_function
    resp = make_response(f(*args, **kwargs))
  File "/app/app.py", line 82, in get_time_dist
    get_time_and_dist(stops, departure_time, arrival_time, school.latitude, school.longitude)
  File "/app/app.py", line 895, in get_time_and_dist
    current_time = current_time + timedelta(seconds=time)
TypeError: unsupported operand type(s) for +: 'NoneType' and 'datetime.timedelta'
2022-02-16 04:29:12,663 DEBUG urllib3.connectionpool ThreadPoolExecutor-0_0 : https://maps.googleapis.com:443 "GET /maps/api/distancematrix/json?destinations=40.78457+-73.95774&origins=40.78174+-73.95491&key=AIzaSyB0b7GWpLob05JP7aVeAt9iMjY0FjDv0_o HTTP/1.1" 200 None
2022-02-16 04:29:12,792 DEBUG urllib3.connectionpool ThreadPoolExecutor-0_0 : https://maps.googleapis.com:443 "GET /maps/api/distancematrix/json?destinations=40.7779857+-73.9558288&origins=40.78457+-73.95774&key=AIzaSyB0b7GWpLob05JP7aVeAt9iMjY0FjDv0_o HTTP/1.1" 200 None
2022-02-16 04:29:13,098 DEBUG urllib3.connectionpool ThreadPoolExecutor-0_0 : https://maps.googleapis.com:443 "GET /maps/api/distancematrix/json?destinations=40.79042+-73.97163&origins=40.7779857+-73.9558288&key=AIzaSyB0b7GWpLob05JP7aVeAt9iMjY0FjDv0_o HTTP/1.1" 200 None
2022-02-16 04:29:13,101 DEBUG root ThreadPoolExecutor-0_0 : [185, 323, 631]
2022-02-16 04:29:13,104 ERROR app ThreadPoolExecutor-0_0 : Exception on /get_time_dist [POST]
Traceback (most recent call last):
  File "/usr/local/lib/python3.8/dist-packages/flask/app.py", line 2073, in wsgi_app
    response = self.full_dispatch_request()
  File "/usr/local/lib/python3.8/dist-packages/flask/app.py", line 1518, in full_dispatch_request
    rv = self.handle_user_exception(e)
  File "/usr/local/lib/python3.8/dist-packages/flask_cors/extension.py", line 165, in wrapped_function
    return cors_after_request(app.make_response(f(*args, **kwargs)))
  File "/usr/local/lib/python3.8/dist-packages/flask/app.py", line 1516, in full_dispatch_request
    rv = self.dispatch_request()
  File "/usr/local/lib/python3.8/dist-packages/flask/app.py", line 1502, in dispatch_request
    return self.ensure_sync(self.view_functions[rule.endpoint])(**req.view_args)
  File "/usr/local/lib/python3.8/dist-packages/flask_cors/decorator.py", line 128, in wrapped_function
    resp = make_response(f(*args, **kwargs))
  File "/app/app.py", line 82, in get_time_dist
    get_time_and_dist(stops, departure_time, arrival_time, school.latitude, school.longitude)
  File "/app/app.py", line 895, in get_time_and_dist
    current_time = current_time + timedelta(seconds=time)
TypeError: unsupported operand type(s) for +: 'datetime.time' and 'datetime.timedelta'
2022-02-16 04:31:33,395 DEBUG urllib3.connectionpool ThreadPoolExecutor-0_0 : Starting new HTTPS connection (1): maps.googleapis.com:443
2022-02-16 04:31:33,879 DEBUG urllib3.connectionpool ThreadPoolExecutor-0_0 : https://maps.googleapis.com:443 "GET /maps/api/distancematrix/json?destinations=40.78457+-73.95774&origins=40.78174+-73.95491&key=AIzaSyB0b7GWpLob05JP7aVeAt9iMjY0FjDv0_o HTTP/1.1" 200 None
2022-02-16 04:31:34,095 DEBUG urllib3.connectionpool ThreadPoolExecutor-0_0 : https://maps.googleapis.com:443 "GET /maps/api/distancematrix/json?destinations=40.7779857+-73.9558288&origins=40.78457+-73.95774&key=AIzaSyB0b7GWpLob05JP7aVeAt9iMjY0FjDv0_o HTTP/1.1" 200 None
2022-02-16 04:31:34,268 DEBUG urllib3.connectionpool ThreadPoolExecutor-0_0 : https://maps.googleapis.com:443 "GET /maps/api/distancematrix/json?destinations=40.79042+-73.97163&origins=40.7779857+-73.9558288&key=AIzaSyB0b7GWpLob05JP7aVeAt9iMjY0FjDv0_o HTTP/1.1" 200 None
2022-02-16 04:31:34,275 DEBUG root ThreadPoolExecutor-0_0 : [185, 323, 631]
2022-02-16 04:31:34,277 ERROR app ThreadPoolExecutor-0_0 : Exception on /get_time_dist [POST]
Traceback (most recent call last):
  File "/usr/local/lib/python3.8/dist-packages/flask/app.py", line 2073, in wsgi_app
    response = self.full_dispatch_request()
  File "/usr/local/lib/python3.8/dist-packages/flask/app.py", line 1518, in full_dispatch_request
    rv = self.handle_user_exception(e)
  File "/usr/local/lib/python3.8/dist-packages/flask_cors/extension.py", line 165, in wrapped_function
    return cors_after_request(app.make_response(f(*args, **kwargs)))
  File "/usr/local/lib/python3.8/dist-packages/flask/app.py", line 1516, in full_dispatch_request
    rv = self.dispatch_request()
  File "/usr/local/lib/python3.8/dist-packages/flask/app.py", line 1502, in dispatch_request
    return self.ensure_sync(self.view_functions[rule.endpoint])(**req.view_args)
  File "/usr/local/lib/python3.8/dist-packages/flask_cors/decorator.py", line 128, in wrapped_function
    resp = make_response(f(*args, **kwargs))
  File "/app/app.py", line 82, in get_time_dist
    get_time_and_dist(stops, departure_time, arrival_time, school.latitude, school.longitude)
  File "/app/app.py", line 895, in get_time_and_dist
    current_time = (current_time + timedelta(seconds=time)).time()
TypeError: unsupported operand type(s) for +: 'datetime.time' and 'datetime.timedelta'
2022-02-16 04:33:57,585 DEBUG urllib3.connectionpool ThreadPoolExecutor-0_0 : Starting new HTTPS connection (1): maps.googleapis.com:443
2022-02-16 04:33:57,918 DEBUG urllib3.connectionpool ThreadPoolExecutor-0_0 : https://maps.googleapis.com:443 "GET /maps/api/distancematrix/json?destinations=40.78457+-73.95774&origins=40.78174+-73.95491&key=AIzaSyB0b7GWpLob05JP7aVeAt9iMjY0FjDv0_o HTTP/1.1" 200 None
2022-02-16 04:33:58,300 DEBUG urllib3.connectionpool ThreadPoolExecutor-0_0 : https://maps.googleapis.com:443 "GET /maps/api/distancematrix/json?destinations=40.7779857+-73.9558288&origins=40.78457+-73.95774&key=AIzaSyB0b7GWpLob05JP7aVeAt9iMjY0FjDv0_o HTTP/1.1" 200 None
2022-02-16 04:33:58,427 DEBUG urllib3.connectionpool ThreadPoolExecutor-0_0 : https://maps.googleapis.com:443 "GET /maps/api/distancematrix/json?destinations=40.79042+-73.97163&origins=40.7779857+-73.9558288&key=AIzaSyB0b7GWpLob05JP7aVeAt9iMjY0FjDv0_o HTTP/1.1" 200 None
2022-02-16 04:33:58,433 DEBUG root ThreadPoolExecutor-0_0 : [185, 323, 631]
2022-02-16 04:33:58,437 ERROR app ThreadPoolExecutor-0_0 : Exception on /get_time_dist [POST]
Traceback (most recent call last):
  File "/usr/local/lib/python3.8/dist-packages/flask/app.py", line 2073, in wsgi_app
    response = self.full_dispatch_request()
  File "/usr/local/lib/python3.8/dist-packages/flask/app.py", line 1518, in full_dispatch_request
    rv = self.handle_user_exception(e)
  File "/usr/local/lib/python3.8/dist-packages/flask_cors/extension.py", line 165, in wrapped_function
    return cors_after_request(app.make_response(f(*args, **kwargs)))
  File "/usr/local/lib/python3.8/dist-packages/flask/app.py", line 1516, in full_dispatch_request
    rv = self.dispatch_request()
  File "/usr/local/lib/python3.8/dist-packages/flask/app.py", line 1502, in dispatch_request
    return self.ensure_sync(self.view_functions[rule.endpoint])(**req.view_args)
  File "/usr/local/lib/python3.8/dist-packages/flask_cors/decorator.py", line 128, in wrapped_function
    resp = make_response(f(*args, **kwargs))
  File "/app/app.py", line 82, in get_time_dist
    get_time_and_dist(stops, departure_time, arrival_time, school.latitude, school.longitude)
  File "/app/app.py", line 892, in get_time_and_dist
    current_time = dt.datetime.combine(dt.date(1,1,1),departure_time)
NameError: name 'dt' is not defined
2022-02-16 04:34:52,022 DEBUG urllib3.connectionpool ThreadPoolExecutor-0_0 : Starting new HTTPS connection (1): maps.googleapis.com:443
2022-02-16 04:34:52,299 DEBUG urllib3.connectionpool ThreadPoolExecutor-0_0 : https://maps.googleapis.com:443 "GET /maps/api/distancematrix/json?destinations=40.78457+-73.95774&origins=40.78174+-73.95491&key=AIzaSyB0b7GWpLob05JP7aVeAt9iMjY0FjDv0_o HTTP/1.1" 200 None
2022-02-16 04:34:52,370 DEBUG urllib3.connectionpool ThreadPoolExecutor-0_0 : https://maps.googleapis.com:443 "GET /maps/api/distancematrix/json?destinations=40.7779857+-73.9558288&origins=40.78457+-73.95774&key=AIzaSyB0b7GWpLob05JP7aVeAt9iMjY0FjDv0_o HTTP/1.1" 200 None
2022-02-16 04:34:52,499 DEBUG urllib3.connectionpool ThreadPoolExecutor-0_0 : https://maps.googleapis.com:443 "GET /maps/api/distancematrix/json?destinations=40.79042+-73.97163&origins=40.7779857+-73.9558288&key=AIzaSyB0b7GWpLob05JP7aVeAt9iMjY0FjDv0_o HTTP/1.1" 200 None
2022-02-16 04:34:52,507 DEBUG root ThreadPoolExecutor-0_0 : [185, 323, 631]
2022-02-16 04:34:52,510 ERROR app ThreadPoolExecutor-0_0 : Exception on /get_time_dist [POST]
Traceback (most recent call last):
  File "/usr/local/lib/python3.8/dist-packages/flask/app.py", line 2073, in wsgi_app
    response = self.full_dispatch_request()
  File "/usr/local/lib/python3.8/dist-packages/flask/app.py", line 1518, in full_dispatch_request
    rv = self.handle_user_exception(e)
  File "/usr/local/lib/python3.8/dist-packages/flask_cors/extension.py", line 165, in wrapped_function
    return cors_after_request(app.make_response(f(*args, **kwargs)))
  File "/usr/local/lib/python3.8/dist-packages/flask/app.py", line 1516, in full_dispatch_request
    rv = self.dispatch_request()
  File "/usr/local/lib/python3.8/dist-packages/flask/app.py", line 1502, in dispatch_request
    return self.ensure_sync(self.view_functions[rule.endpoint])(**req.view_args)
  File "/usr/local/lib/python3.8/dist-packages/flask_cors/decorator.py", line 128, in wrapped_function
    resp = make_response(f(*args, **kwargs))
  File "/app/app.py", line 82, in get_time_dist
    get_time_and_dist(stops, departure_time, arrival_time, school.latitude, school.longitude)
  File "/app/app.py", line 892, in get_time_and_dist
    current_time = datetime.datetime.combine(datetime.date(1,1,1),departure_time)
AttributeError: type object 'datetime.datetime' has no attribute 'datetime'
2022-02-16 04:35:25,874 DEBUG urllib3.connectionpool ThreadPoolExecutor-0_0 : Starting new HTTPS connection (1): maps.googleapis.com:443
2022-02-16 04:35:26,099 DEBUG urllib3.connectionpool ThreadPoolExecutor-0_0 : https://maps.googleapis.com:443 "GET /maps/api/distancematrix/json?destinations=40.78457+-73.95774&origins=40.78174+-73.95491&key=AIzaSyB0b7GWpLob05JP7aVeAt9iMjY0FjDv0_o HTTP/1.1" 200 None
2022-02-16 04:35:26,381 DEBUG urllib3.connectionpool ThreadPoolExecutor-0_0 : https://maps.googleapis.com:443 "GET /maps/api/distancematrix/json?destinations=40.7779857+-73.9558288&origins=40.78457+-73.95774&key=AIzaSyB0b7GWpLob05JP7aVeAt9iMjY0FjDv0_o HTTP/1.1" 200 None
2022-02-16 04:35:26,446 DEBUG urllib3.connectionpool ThreadPoolExecutor-0_0 : https://maps.googleapis.com:443 "GET /maps/api/distancematrix/json?destinations=40.79042+-73.97163&origins=40.7779857+-73.9558288&key=AIzaSyB0b7GWpLob05JP7aVeAt9iMjY0FjDv0_o HTTP/1.1" 200 None
2022-02-16 04:35:26,452 DEBUG root ThreadPoolExecutor-0_0 : [185, 323, 631]
2022-02-16 04:35:26,454 ERROR app ThreadPoolExecutor-0_0 : Exception on /get_time_dist [POST]
Traceback (most recent call last):
  File "/usr/local/lib/python3.8/dist-packages/flask/app.py", line 2073, in wsgi_app
    response = self.full_dispatch_request()
  File "/usr/local/lib/python3.8/dist-packages/flask/app.py", line 1518, in full_dispatch_request
    rv = self.handle_user_exception(e)
  File "/usr/local/lib/python3.8/dist-packages/flask_cors/extension.py", line 165, in wrapped_function
    return cors_after_request(app.make_response(f(*args, **kwargs)))
  File "/usr/local/lib/python3.8/dist-packages/flask/app.py", line 1516, in full_dispatch_request
    rv = self.dispatch_request()
  File "/usr/local/lib/python3.8/dist-packages/flask/app.py", line 1502, in dispatch_request
    return self.ensure_sync(self.view_functions[rule.endpoint])(**req.view_args)
  File "/usr/local/lib/python3.8/dist-packages/flask_cors/decorator.py", line 128, in wrapped_function
    resp = make_response(f(*args, **kwargs))
  File "/app/app.py", line 82, in get_time_dist
    get_time_and_dist(stops, departure_time, arrival_time, school.latitude, school.longitude)
  File "/app/app.py", line 892, in get_time_and_dist
    current_time = datetime.combine(date(1,1,1),departure_time)
NameError: name 'date' is not defined
2022-02-16 04:35:55,353 DEBUG urllib3.connectionpool ThreadPoolExecutor-0_0 : Starting new HTTPS connection (1): maps.googleapis.com:443
2022-02-16 04:35:55,751 DEBUG urllib3.connectionpool ThreadPoolExecutor-0_0 : https://maps.googleapis.com:443 "GET /maps/api/distancematrix/json?destinations=40.78457+-73.95774&origins=40.78174+-73.95491&key=AIzaSyB0b7GWpLob05JP7aVeAt9iMjY0FjDv0_o HTTP/1.1" 200 None
2022-02-16 04:35:55,807 DEBUG urllib3.connectionpool ThreadPoolExecutor-0_0 : https://maps.googleapis.com:443 "GET /maps/api/distancematrix/json?destinations=40.7779857+-73.9558288&origins=40.78457+-73.95774&key=AIzaSyB0b7GWpLob05JP7aVeAt9iMjY0FjDv0_o HTTP/1.1" 200 None
2022-02-16 04:35:55,911 DEBUG urllib3.connectionpool ThreadPoolExecutor-0_0 : https://maps.googleapis.com:443 "GET /maps/api/distancematrix/json?destinations=40.79042+-73.97163&origins=40.7779857+-73.9558288&key=AIzaSyB0b7GWpLob05JP7aVeAt9iMjY0FjDv0_o HTTP/1.1" 200 None
2022-02-16 04:35:55,918 DEBUG root ThreadPoolExecutor-0_0 : [185, 323, 631]
2022-02-16 04:35:55,920 DEBUG root ThreadPoolExecutor-0_0 : [datetime.time(15, 3, 5), datetime.time(15, 8, 28), datetime.time(15, 18, 59)]
2022-02-16 04:35:55,924 DEBUG root ThreadPoolExecutor-0_0 : [datetime.time(9, 26, 55), datetime.time(9, 21, 32), datetime.time(9, 11, 1)]
2022-02-16 04:55:28,514 DEBUG urllib3.connectionpool ThreadPoolExecutor-0_0 : Starting new HTTPS connection (1): maps.googleapis.com:443
2022-02-16 04:55:29,054 DEBUG urllib3.connectionpool ThreadPoolExecutor-0_0 : https://maps.googleapis.com:443 "GET /maps/api/distancematrix/json?destinations=40.78457+-73.95774&origins=40.78174+-73.95491&key=AIzaSyB0b7GWpLob05JP7aVeAt9iMjY0FjDv0_o HTTP/1.1" 200 None
2022-02-16 04:55:29,257 DEBUG urllib3.connectionpool ThreadPoolExecutor-0_0 : https://maps.googleapis.com:443 "GET /maps/api/distancematrix/json?destinations=40.7779857+-73.9558288&origins=40.78457+-73.95774&key=AIzaSyB0b7GWpLob05JP7aVeAt9iMjY0FjDv0_o HTTP/1.1" 200 None
2022-02-16 04:55:29,441 DEBUG urllib3.connectionpool ThreadPoolExecutor-0_0 : https://maps.googleapis.com:443 "GET /maps/api/distancematrix/json?destinations=40.79042+-73.97163&origins=40.7779857+-73.9558288&key=AIzaSyB0b7GWpLob05JP7aVeAt9iMjY0FjDv0_o HTTP/1.1" 200 None
2022-02-16 04:55:29,444 DEBUG root ThreadPoolExecutor-0_0 : [185, 323, 631]
2022-02-16 04:55:29,445 DEBUG root ThreadPoolExecutor-0_0 : [datetime.time(15, 3, 5), datetime.time(15, 8, 28), datetime.time(15, 18, 59)]
2022-02-16 04:55:29,447 DEBUG root ThreadPoolExecutor-0_0 : [datetime.time(9, 26, 55), datetime.time(9, 21, 32), datetime.time(9, 11, 1)]
2022-02-16 04:56:57,753 DEBUG urllib3.connectionpool ThreadPoolExecutor-0_0 : Starting new HTTPS connection (1): maps.googleapis.com:443
2022-02-16 04:56:58,254 DEBUG urllib3.connectionpool ThreadPoolExecutor-0_0 : https://maps.googleapis.com:443 "GET /maps/api/distancematrix/json?destinations=40.78457+-73.95774&origins=40.78174+-73.95491&key=AIzaSyB0b7GWpLob05JP7aVeAt9iMjY0FjDv0_o HTTP/1.1" 200 None
2022-02-16 04:56:58,385 DEBUG urllib3.connectionpool ThreadPoolExecutor-0_0 : https://maps.googleapis.com:443 "GET /maps/api/distancematrix/json?destinations=40.7779857+-73.9558288&origins=40.78457+-73.95774&key=AIzaSyB0b7GWpLob05JP7aVeAt9iMjY0FjDv0_o HTTP/1.1" 200 None
2022-02-16 04:56:58,494 DEBUG urllib3.connectionpool ThreadPoolExecutor-0_0 : https://maps.googleapis.com:443 "GET /maps/api/distancematrix/json?destinations=40.79042+-73.97163&origins=40.7779857+-73.9558288&key=AIzaSyB0b7GWpLob05JP7aVeAt9iMjY0FjDv0_o HTTP/1.1" 200 None
2022-02-16 04:56:58,502 DEBUG root ThreadPoolExecutor-0_0 : [185, 323, 631]
2022-02-16 04:56:58,504 DEBUG root ThreadPoolExecutor-0_0 : [datetime.time(15, 3, 5), datetime.time(15, 8, 28), datetime.time(15, 18, 59)]
2022-02-16 04:56:58,506 DEBUG root ThreadPoolExecutor-0_0 : [datetime.time(9, 26, 55), datetime.time(9, 21, 32), datetime.time(9, 11, 1)]
2022-02-16 04:58:13,397 DEBUG urllib3.connectionpool ThreadPoolExecutor-0_0 : Starting new HTTPS connection (1): maps.googleapis.com:443
2022-02-16 04:58:13,746 DEBUG urllib3.connectionpool ThreadPoolExecutor-0_0 : https://maps.googleapis.com:443 "GET /maps/api/distancematrix/json?destinations=40.78457+-73.95774&origins=40.78174+-73.95491&key=AIzaSyB0b7GWpLob05JP7aVeAt9iMjY0FjDv0_o HTTP/1.1" 200 None
2022-02-16 04:58:13,857 DEBUG urllib3.connectionpool ThreadPoolExecutor-0_0 : https://maps.googleapis.com:443 "GET /maps/api/distancematrix/json?destinations=40.7779857+-73.9558288&origins=40.78457+-73.95774&key=AIzaSyB0b7GWpLob05JP7aVeAt9iMjY0FjDv0_o HTTP/1.1" 200 None
2022-02-16 04:58:14,138 DEBUG urllib3.connectionpool ThreadPoolExecutor-0_0 : https://maps.googleapis.com:443 "GET /maps/api/distancematrix/json?destinations=40.79042+-73.97163&origins=40.7779857+-73.9558288&key=AIzaSyB0b7GWpLob05JP7aVeAt9iMjY0FjDv0_o HTTP/1.1" 200 None
2022-02-16 04:58:14,142 DEBUG root ThreadPoolExecutor-0_0 : [185, 323, 631]
2022-02-16 04:58:14,143 DEBUG root ThreadPoolExecutor-0_0 : [datetime.time(15, 3, 5), datetime.time(15, 8, 28), datetime.time(15, 18, 59)]
2022-02-16 04:58:14,145 DEBUG root ThreadPoolExecutor-0_0 : [datetime.time(9, 26, 55), datetime.time(9, 21, 32), datetime.time(9, 11, 1)]
2022-02-16 04:58:14,158 ERROR app ThreadPoolExecutor-0_0 : Exception on /route [POST]
Traceback (most recent call last):
  File "/usr/local/lib/python3.8/dist-packages/sqlalchemy/engine/base.py", line 1782, in _execute_context
    self.dialect.do_executemany(
  File "/usr/local/lib/python3.8/dist-packages/sqlalchemy/dialects/postgresql/psycopg2.py", line 951, in do_executemany
    context._psycopg2_fetched_rows = xtras.execute_values(
  File "/usr/local/lib/python3.8/dist-packages/psycopg2/extras.py", line 1270, in execute_values
    cur.execute(b''.join(parts))
psycopg2.errors.UndefinedColumn: column "index" of relation "stops" does not exist
LINE 1: ...ime, dropoff_time, route_id, longitude, latitude, index) VAL...
                                                             ^


The above exception was the direct cause of the following exception:

Traceback (most recent call last):
  File "/usr/local/lib/python3.8/dist-packages/flask/app.py", line 2073, in wsgi_app
    response = self.full_dispatch_request()
  File "/usr/local/lib/python3.8/dist-packages/flask/app.py", line 1518, in full_dispatch_request
    rv = self.handle_user_exception(e)
  File "/usr/local/lib/python3.8/dist-packages/flask_cors/extension.py", line 165, in wrapped_function
    return cors_after_request(app.make_response(f(*args, **kwargs)))
  File "/usr/local/lib/python3.8/dist-packages/flask/app.py", line 1516, in full_dispatch_request
    rv = self.dispatch_request()
  File "/usr/local/lib/python3.8/dist-packages/flask/app.py", line 1502, in dispatch_request
    return self.ensure_sync(self.view_functions[rule.endpoint])(**req.view_args)
  File "/usr/local/lib/python3.8/dist-packages/flask_cors/decorator.py", line 128, in wrapped_function
    resp = make_response(f(*args, **kwargs))
  File "/app/app.py", line 46, in decorator
    return fn(*args, **kwargs)
  File "/app/app.py", line 746, in routes
    db.session.commit()
  File "<string>", line 2, in commit
  File "/usr/local/lib/python3.8/dist-packages/sqlalchemy/orm/session.py", line 1431, in commit
    self._transaction.commit(_to_root=self.future)
  File "/usr/local/lib/python3.8/dist-packages/sqlalchemy/orm/session.py", line 829, in commit
    self._prepare_impl()
  File "/usr/local/lib/python3.8/dist-packages/sqlalchemy/orm/session.py", line 808, in _prepare_impl
    self.session.flush()
  File "/usr/local/lib/python3.8/dist-packages/sqlalchemy/orm/session.py", line 3363, in flush
    self._flush(objects)
  File "/usr/local/lib/python3.8/dist-packages/sqlalchemy/orm/session.py", line 3503, in _flush
    transaction.rollback(_capture_exception=True)
  File "/usr/local/lib/python3.8/dist-packages/sqlalchemy/util/langhelpers.py", line 70, in __exit__
    compat.raise_(
  File "/usr/local/lib/python3.8/dist-packages/sqlalchemy/util/compat.py", line 207, in raise_
    raise exception
  File "/usr/local/lib/python3.8/dist-packages/sqlalchemy/orm/session.py", line 3463, in _flush
    flush_context.execute()
  File "/usr/local/lib/python3.8/dist-packages/sqlalchemy/orm/unitofwork.py", line 456, in execute
    rec.execute(self)
  File "/usr/local/lib/python3.8/dist-packages/sqlalchemy/orm/unitofwork.py", line 630, in execute
    util.preloaded.orm_persistence.save_obj(
  File "/usr/local/lib/python3.8/dist-packages/sqlalchemy/orm/persistence.py", line 244, in save_obj
    _emit_insert_statements(
  File "/usr/local/lib/python3.8/dist-packages/sqlalchemy/orm/persistence.py", line 1155, in _emit_insert_statements
    c = connection._execute_20(
  File "/usr/local/lib/python3.8/dist-packages/sqlalchemy/engine/base.py", line 1614, in _execute_20
    return meth(self, args_10style, kwargs_10style, execution_options)
  File "/usr/local/lib/python3.8/dist-packages/sqlalchemy/sql/elements.py", line 325, in _execute_on_connection
    return connection._execute_clauseelement(
  File "/usr/local/lib/python3.8/dist-packages/sqlalchemy/engine/base.py", line 1481, in _execute_clauseelement
    ret = self._execute_context(
  File "/usr/local/lib/python3.8/dist-packages/sqlalchemy/engine/base.py", line 1845, in _execute_context
    self._handle_dbapi_exception(
  File "/usr/local/lib/python3.8/dist-packages/sqlalchemy/engine/base.py", line 2026, in _handle_dbapi_exception
    util.raise_(
  File "/usr/local/lib/python3.8/dist-packages/sqlalchemy/util/compat.py", line 207, in raise_
    raise exception
  File "/usr/local/lib/python3.8/dist-packages/sqlalchemy/engine/base.py", line 1782, in _execute_context
    self.dialect.do_executemany(
  File "/usr/local/lib/python3.8/dist-packages/sqlalchemy/dialects/postgresql/psycopg2.py", line 951, in do_executemany
    context._psycopg2_fetched_rows = xtras.execute_values(
  File "/usr/local/lib/python3.8/dist-packages/psycopg2/extras.py", line 1270, in execute_values
    cur.execute(b''.join(parts))
sqlalchemy.exc.ProgrammingError: (psycopg2.errors.UndefinedColumn) column "index" of relation "stops" does not exist
LINE 1: ...ime, dropoff_time, route_id, longitude, latitude, index) VAL...
                                                             ^

[SQL: INSERT INTO stops (name, pickup_time, dropoff_time, route_id, longitude, latitude, index) VALUES (%(name)s, %(pickup_time)s, %(dropoff_time)s, %(route_id)s, %(longitude)s, %(latitude)s, %(index)s) RETURNING stops.id]
[parameters: ({'name': 'stop1', 'pickup_time': datetime.time(9, 26, 55), 'dropoff_time': datetime.time(15, 3, 5), 'route_id': 5, 'longitude': -73.95774, 'latitude': 40.78457, 'index': 0}, {'name': 'stop2', 'pickup_time': datetime.time(9, 21, 32), 'dropoff_time': datetime.time(15, 8, 28), 'route_id': 5, 'longitude': -73.9558288, 'latitude': 40.7779857, 'index': 1}, {'name': 'stop3', 'pickup_time': datetime.time(9, 11, 1), 'dropoff_time': datetime.time(15, 18, 59), 'route_id': 5, 'longitude': -73.97163, 'latitude': 40.79042, 'index': 2})]
(Background on this error at: https://sqlalche.me/e/14/f405)
2022-02-16 05:00:15,958 DEBUG urllib3.connectionpool MainThread : Starting new HTTPS connection (1): maps.googleapis.com:443
2022-02-16 05:00:16,457 DEBUG urllib3.connectionpool MainThread : https://maps.googleapis.com:443 "GET /maps/api/geocode/json?address=401+Chapel+Dr%2C+Durham%2C+NC+27705&key=AIzaSyB0b7GWpLob05JP7aVeAt9iMjY0FjDv0_o HTTP/1.1" 200 None
2022-02-16 05:00:22,753 DEBUG urllib3.connectionpool MainThread : Starting new HTTPS connection (1): maps.googleapis.com:443
2022-02-16 05:00:23,180 DEBUG urllib3.connectionpool MainThread : https://maps.googleapis.com:443 "GET /maps/api/geocode/json?address=11256+Palos+Verdes+Court%2C+Cupertino%2C+CA+95014&key=AIzaSyB0b7GWpLob05JP7aVeAt9iMjY0FjDv0_o HTTP/1.1" 200 None
2022-02-16 05:00:23,579 DEBUG urllib3.connectionpool MainThread : https://maps.googleapis.com:443 "GET /maps/api/geocode/json?address=14524+Lodestar+Drive%2C+Grass+Valley%2C+CA+95949&key=AIzaSyB0b7GWpLob05JP7aVeAt9iMjY0FjDv0_o HTTP/1.1" 200 None
2022-02-16 05:00:23,966 DEBUG urllib3.connectionpool MainThread : https://maps.googleapis.com:443 "GET /maps/api/geocode/json?address=4329+Howe+Street%2C+Oakland%2C+CA+94611&key=AIzaSyB0b7GWpLob05JP7aVeAt9iMjY0FjDv0_o HTTP/1.1" 200 None
2022-02-16 05:00:24,296 DEBUG urllib3.connectionpool MainThread : https://maps.googleapis.com:443 "GET /maps/api/geocode/json?address=11+Eclipse+Court%2C+Alameda%2C+CA+94501&key=AIzaSyB0b7GWpLob05JP7aVeAt9iMjY0FjDv0_o HTTP/1.1" 200 None
2022-02-16 05:00:24,707 DEBUG urllib3.connectionpool MainThread : https://maps.googleapis.com:443 "GET /maps/api/geocode/json?address=6420+Via+Baron%2C+Rancho+Palos+Verdes%2C+CA+90275&key=AIzaSyB0b7GWpLob05JP7aVeAt9iMjY0FjDv0_o HTTP/1.1" 200 None
2022-02-16 05:00:25,282 DEBUG urllib3.connectionpool MainThread : https://maps.googleapis.com:443 "GET /maps/api/geocode/json?address=5472+Sunstar+Common%2C+Fremont%2C+CA+94555&key=AIzaSyB0b7GWpLob05JP7aVeAt9iMjY0FjDv0_o HTTP/1.1" 200 None
2022-02-16 05:00:25,788 DEBUG urllib3.connectionpool MainThread : https://maps.googleapis.com:443 "GET /maps/api/geocode/json?address=5397+Wentworth+Avenue%2C+Oakland%2C+CA+94601&key=AIzaSyB0b7GWpLob05JP7aVeAt9iMjY0FjDv0_o HTTP/1.1" 200 None
2022-02-16 05:00:26,343 DEBUG urllib3.connectionpool MainThread : https://maps.googleapis.com:443 "GET /maps/api/geocode/json?address=2640+8th+Avenue%2C+Oakland%2C+CA+94606&key=AIzaSyB0b7GWpLob05JP7aVeAt9iMjY0FjDv0_o HTTP/1.1" 200 None
2022-02-16 05:00:26,731 DEBUG urllib3.connectionpool MainThread : https://maps.googleapis.com:443 "GET /maps/api/geocode/json?address=1870+A+Street%2C+Oroville%2C+CA+95966&key=AIzaSyB0b7GWpLob05JP7aVeAt9iMjY0FjDv0_o HTTP/1.1" 200 None
2022-02-16 05:00:27,093 DEBUG urllib3.connectionpool MainThread : https://maps.googleapis.com:443 "GET /maps/api/geocode/json?address=775+47th+Street%2C+Oakland%2C+CA+94609&key=AIzaSyB0b7GWpLob05JP7aVeAt9iMjY0FjDv0_o HTTP/1.1" 200 None
2022-02-16 05:00:27,470 DEBUG urllib3.connectionpool MainThread : https://maps.googleapis.com:443 "GET /maps/api/geocode/json?address=51035+Conifer+Drive%2C+Soda+Springs%2C+CA+95728&key=AIzaSyB0b7GWpLob05JP7aVeAt9iMjY0FjDv0_o HTTP/1.1" 200 None
2022-02-16 05:00:27,781 DEBUG urllib3.connectionpool MainThread : https://maps.googleapis.com:443 "GET /maps/api/geocode/json?address=450+C+Street%2C+Hayward%2C+CA+94541&key=AIzaSyB0b7GWpLob05JP7aVeAt9iMjY0FjDv0_o HTTP/1.1" 200 None
2022-02-16 05:00:28,116 DEBUG urllib3.connectionpool MainThread : https://maps.googleapis.com:443 "GET /maps/api/geocode/json?address=3827+West+Chapman+Avenue%2C+Orange%2C+CA+92868&key=AIzaSyB0b7GWpLob05JP7aVeAt9iMjY0FjDv0_o HTTP/1.1" 200 None
2022-02-16 05:00:28,425 DEBUG urllib3.connectionpool MainThread : https://maps.googleapis.com:443 "GET /maps/api/geocode/json?address=37600+Sycamore+Street%2C+Newark%2C+CA+94560&key=AIzaSyB0b7GWpLob05JP7aVeAt9iMjY0FjDv0_o HTTP/1.1" 200 None
2022-02-16 05:00:28,791 DEBUG urllib3.connectionpool MainThread : https://maps.googleapis.com:443 "GET /maps/api/geocode/json?address=4920+Quonset+Drive%2C+Sacramento%2C+CA+95820&key=AIzaSyB0b7GWpLob05JP7aVeAt9iMjY0FjDv0_o HTTP/1.1" 200 None
2022-02-16 05:00:29,118 DEBUG urllib3.connectionpool MainThread : https://maps.googleapis.com:443 "GET /maps/api/geocode/json?address=4500+Margalo+Avenue%2C+Bakersfield%2C+CA+93313&key=AIzaSyB0b7GWpLob05JP7aVeAt9iMjY0FjDv0_o HTTP/1.1" 200 None
2022-02-16 05:00:29,453 DEBUG urllib3.connectionpool MainThread : https://maps.googleapis.com:443 "GET /maps/api/geocode/json?address=7800+River+Mist+Avenue%2C+Bakersfield%2C+CA+93313&key=AIzaSyB0b7GWpLob05JP7aVeAt9iMjY0FjDv0_o HTTP/1.1" 200 None
2022-02-16 05:00:29,865 DEBUG urllib3.connectionpool MainThread : https://maps.googleapis.com:443 "GET /maps/api/geocode/json?address=21950+Arnold+Center+Road%2C+Carson%2C+CA+90810&key=AIzaSyB0b7GWpLob05JP7aVeAt9iMjY0FjDv0_o HTTP/1.1" 200 None
2022-02-16 05:00:30,194 DEBUG urllib3.connectionpool MainThread : https://maps.googleapis.com:443 "GET /maps/api/geocode/json?address=10202+Vista+Drive%2C+Cupertino%2C+CA+95014&key=AIzaSyB0b7GWpLob05JP7aVeAt9iMjY0FjDv0_o HTTP/1.1" 200 None
2022-02-16 05:00:30,258 DEBUG urllib3.connectionpool MainThread : https://maps.googleapis.com:443 "GET /maps/api/geocode/json?address=5397+Wentworth+Avenue%2C+Oakland%2C+CA+94601&key=AIzaSyB0b7GWpLob05JP7aVeAt9iMjY0FjDv0_o HTTP/1.1" 200 None
2022-02-16 05:00:30,605 DEBUG urllib3.connectionpool MainThread : https://maps.googleapis.com:443 "GET /maps/api/geocode/json?address=2708+Mabel+Street%2C+Berkeley%2C+CA+94702&key=AIzaSyB0b7GWpLob05JP7aVeAt9iMjY0FjDv0_o HTTP/1.1" 200 None
2022-02-16 05:00:30,895 DEBUG urllib3.connectionpool MainThread : https://maps.googleapis.com:443 "GET /maps/api/geocode/json?address=26466+Mockingbird+Lane%2C+Hayward%2C+CA+94544&key=AIzaSyB0b7GWpLob05JP7aVeAt9iMjY0FjDv0_o HTTP/1.1" 200 None
2022-02-16 05:00:31,288 DEBUG urllib3.connectionpool MainThread : https://maps.googleapis.com:443 "GET /maps/api/geocode/json?address=2443+Sierra+Nevada+Road%2C+Mammoth+Lakes%2C+CA+93546&key=AIzaSyB0b7GWpLob05JP7aVeAt9iMjY0FjDv0_o HTTP/1.1" 200 None
2022-02-16 05:00:31,623 DEBUG urllib3.connectionpool MainThread : https://maps.googleapis.com:443 "GET /maps/api/geocode/json?address=3027+Badger+Drive%2C+Pleasanton%2C+CA+94566&key=AIzaSyB0b7GWpLob05JP7aVeAt9iMjY0FjDv0_o HTTP/1.1" 200 None
2022-02-16 05:00:32,073 DEBUG urllib3.connectionpool MainThread : https://maps.googleapis.com:443 "GET /maps/api/geocode/json?address=1+Kelton+Court%2C+Oakland%2C+CA+94611&key=AIzaSyB0b7GWpLob05JP7aVeAt9iMjY0FjDv0_o HTTP/1.1" 200 None
2022-02-16 05:00:32,365 DEBUG urllib3.connectionpool MainThread : https://maps.googleapis.com:443 "GET /maps/api/geocode/json?address=649+Praderia+Circle%2C+Fremont%2C+CA+94539&key=AIzaSyB0b7GWpLob05JP7aVeAt9iMjY0FjDv0_o HTTP/1.1" 200 None
2022-02-16 05:00:32,899 DEBUG urllib3.connectionpool MainThread : https://maps.googleapis.com:443 "GET /maps/api/geocode/json?address=680+Quintana+Road%2C+Morro+Bay%2C+CA+93442&key=AIzaSyB0b7GWpLob05JP7aVeAt9iMjY0FjDv0_o HTTP/1.1" 200 None
2022-02-16 05:00:33,281 DEBUG urllib3.connectionpool MainThread : https://maps.googleapis.com:443 "GET /maps/api/geocode/json?address=2747+68th+Avenue%2C+Oakland%2C+CA+94605&key=AIzaSyB0b7GWpLob05JP7aVeAt9iMjY0FjDv0_o HTTP/1.1" 200 None
2022-02-16 05:00:33,651 DEBUG urllib3.connectionpool MainThread : https://maps.googleapis.com:443 "GET /maps/api/geocode/json?address=1234+Carmel+Street%2C+Madera%2C+CA+93638&key=AIzaSyB0b7GWpLob05JP7aVeAt9iMjY0FjDv0_o HTTP/1.1" 200 None
2022-02-16 05:00:34,043 DEBUG urllib3.connectionpool MainThread : https://maps.googleapis.com:443 "GET /maps/api/geocode/json?address=2755+Country+Drive%2C+Fremont%2C+CA+94536&key=AIzaSyB0b7GWpLob05JP7aVeAt9iMjY0FjDv0_o HTTP/1.1" 200 None
2022-02-16 05:00:34,315 DEBUG urllib3.connectionpool MainThread : https://maps.googleapis.com:443 "GET /maps/api/geocode/json?address=36360+Beech+Place%2C+Newark%2C+CA+94560&key=AIzaSyB0b7GWpLob05JP7aVeAt9iMjY0FjDv0_o HTTP/1.1" 200 None
2022-02-16 05:00:34,715 DEBUG urllib3.connectionpool MainThread : https://maps.googleapis.com:443 "GET /maps/api/geocode/json?address=514+Flower+Lane%2C+Alameda%2C+CA+94502&key=AIzaSyB0b7GWpLob05JP7aVeAt9iMjY0FjDv0_o HTTP/1.1" 200 None
2022-02-16 05:00:35,134 DEBUG urllib3.connectionpool MainThread : https://maps.googleapis.com:443 "GET /maps/api/geocode/json?address=1357+Addison+Street%2C+Berkeley%2C+CA+94702&key=AIzaSyB0b7GWpLob05JP7aVeAt9iMjY0FjDv0_o HTTP/1.1" 200 None
2022-02-16 05:00:35,394 DEBUG urllib3.connectionpool MainThread : https://maps.googleapis.com:443 "GET /maps/api/geocode/json?address=8934+Arrowrock+Trail%2C+Smartsville%2C+CA+95977&key=AIzaSyB0b7GWpLob05JP7aVeAt9iMjY0FjDv0_o HTTP/1.1" 200 None
2022-02-16 05:00:35,747 DEBUG urllib3.connectionpool MainThread : https://maps.googleapis.com:443 "GET /maps/api/geocode/json?address=2409+Park+Street%2C+Selma%2C+CA+93662&key=AIzaSyB0b7GWpLob05JP7aVeAt9iMjY0FjDv0_o HTTP/1.1" 200 None
2022-02-16 05:00:35,818 DEBUG urllib3.connectionpool MainThread : https://maps.googleapis.com:443 "GET /maps/api/geocode/json?address=4920+Quonset+Drive%2C+Sacramento%2C+CA+95820&key=AIzaSyB0b7GWpLob05JP7aVeAt9iMjY0FjDv0_o HTTP/1.1" 200 None
2022-02-16 05:00:36,310 DEBUG urllib3.connectionpool MainThread : https://maps.googleapis.com:443 "GET /maps/api/geocode/json?address=12091+Mierkey+Road%2C+Jackson%2C+CA+95642&key=AIzaSyB0b7GWpLob05JP7aVeAt9iMjY0FjDv0_o HTTP/1.1" 200 None
2022-02-16 05:00:36,796 DEBUG urllib3.connectionpool MainThread : https://maps.googleapis.com:443 "GET /maps/api/geocode/json?address=5725+Medallion+Court%2C+Castro+Valley%2C+CA+94552&key=AIzaSyB0b7GWpLob05JP7aVeAt9iMjY0FjDv0_o HTTP/1.1" 200 None
2022-02-16 05:00:37,189 DEBUG urllib3.connectionpool MainThread : https://maps.googleapis.com:443 "GET /maps/api/geocode/json?address=894+Windmill+Park+Lane%2C+Mountain+View%2C+CA+94043&key=AIzaSyB0b7GWpLob05JP7aVeAt9iMjY0FjDv0_o HTTP/1.1" 200 None
2022-02-16 05:00:37,485 DEBUG urllib3.connectionpool MainThread : https://maps.googleapis.com:443 "GET /maps/api/geocode/json?address=1300+Lemos+Lane%2C+Fremont%2C+CA+94539&key=AIzaSyB0b7GWpLob05JP7aVeAt9iMjY0FjDv0_o HTTP/1.1" 200 None
2022-02-16 05:02:25,238 DEBUG urllib3.connectionpool ThreadPoolExecutor-0_0 : Resetting dropped connection: maps.googleapis.com
2022-02-16 05:02:25,515 DEBUG urllib3.connectionpool ThreadPoolExecutor-0_0 : https://maps.googleapis.com:443 "GET /maps/api/distancematrix/json?destinations=40.78457+-73.95774&origins=40.78174+-73.95491&key=AIzaSyB0b7GWpLob05JP7aVeAt9iMjY0FjDv0_o HTTP/1.1" 200 None
2022-02-16 05:02:25,613 DEBUG urllib3.connectionpool ThreadPoolExecutor-0_0 : https://maps.googleapis.com:443 "GET /maps/api/distancematrix/json?destinations=40.7779857+-73.9558288&origins=40.78457+-73.95774&key=AIzaSyB0b7GWpLob05JP7aVeAt9iMjY0FjDv0_o HTTP/1.1" 200 None
2022-02-16 05:02:25,684 DEBUG urllib3.connectionpool ThreadPoolExecutor-0_0 : https://maps.googleapis.com:443 "GET /maps/api/distancematrix/json?destinations=40.79042+-73.97163&origins=40.7779857+-73.9558288&key=AIzaSyB0b7GWpLob05JP7aVeAt9iMjY0FjDv0_o HTTP/1.1" 200 None
2022-02-16 05:02:25,690 DEBUG root ThreadPoolExecutor-0_0 : [185, 323, 631]
2022-02-16 05:02:25,693 DEBUG root ThreadPoolExecutor-0_0 : [datetime.time(15, 3, 5), datetime.time(15, 8, 28), datetime.time(15, 18, 59)]
2022-02-16 05:02:25,695 DEBUG root ThreadPoolExecutor-0_0 : [datetime.time(7, 56, 55), datetime.time(7, 51, 32), datetime.time(7, 41, 1)]
2022-02-16 05:16:06,700 ERROR app ThreadPoolExecutor-0_0 : Exception on /route [POST]
Traceback (most recent call last):
  File "/usr/local/lib/python3.8/dist-packages/flask/app.py", line 2073, in wsgi_app
    response = self.full_dispatch_request()
  File "/usr/local/lib/python3.8/dist-packages/flask/app.py", line 1518, in full_dispatch_request
    rv = self.handle_user_exception(e)
  File "/usr/local/lib/python3.8/dist-packages/flask_cors/extension.py", line 165, in wrapped_function
    return cors_after_request(app.make_response(f(*args, **kwargs)))
  File "/usr/local/lib/python3.8/dist-packages/flask/app.py", line 1516, in full_dispatch_request
    rv = self.dispatch_request()
  File "/usr/local/lib/python3.8/dist-packages/flask/app.py", line 1502, in dispatch_request
    return self.ensure_sync(self.view_functions[rule.endpoint])(**req.view_args)
  File "/usr/local/lib/python3.8/dist-packages/flask_cors/decorator.py", line 128, in wrapped_function
    resp = make_response(f(*args, **kwargs))
  File "/app/app.py", line 46, in decorator
    return fn(*args, **kwargs)
  File "/app/app.py", line 724, in routes
    sorted_stops = sorted(stops.items(), key=lambda x: x['index'])
AttributeError: 'list' object has no attribute 'items'
2022-02-16 05:17:35,638 DEBUG urllib3.connectionpool ThreadPoolExecutor-0_0 : Starting new HTTPS connection (1): maps.googleapis.com:443
2022-02-16 05:17:36,228 DEBUG urllib3.connectionpool ThreadPoolExecutor-0_0 : https://maps.googleapis.com:443 "GET /maps/api/distancematrix/json?destinations=40.7779857+-73.9558288&origins=40.78174+-73.95491&key=AIzaSyB0b7GWpLob05JP7aVeAt9iMjY0FjDv0_o HTTP/1.1" 200 None
2022-02-16 05:17:36,391 DEBUG urllib3.connectionpool ThreadPoolExecutor-0_0 : https://maps.googleapis.com:443 "GET /maps/api/distancematrix/json?destinations=40.79042+-73.97163&origins=40.7779857+-73.9558288&key=AIzaSyB0b7GWpLob05JP7aVeAt9iMjY0FjDv0_o HTTP/1.1" 200 None
2022-02-16 05:17:36,561 DEBUG urllib3.connectionpool ThreadPoolExecutor-0_0 : https://maps.googleapis.com:443 "GET /maps/api/distancematrix/json?destinations=40.78457+-73.95774&origins=40.79042+-73.97163&key=AIzaSyB0b7GWpLob05JP7aVeAt9iMjY0FjDv0_o HTTP/1.1" 200 None
2022-02-16 05:17:36,568 DEBUG root ThreadPoolExecutor-0_0 : [244, 631, 622]
2022-02-16 05:17:36,573 DEBUG root ThreadPoolExecutor-0_0 : [datetime.time(15, 4, 4), datetime.time(15, 14, 35), datetime.time(15, 24, 57)]
2022-02-16 05:17:36,574 DEBUG root ThreadPoolExecutor-0_0 : [datetime.time(7, 55, 56), datetime.time(7, 45, 25), datetime.time(7, 35, 3)]
