2022-02-11 15:20:17,588 DEBUG urllib3.connectionpool MainThread : Starting new HTTPS connection (1): maps.googleapis.com:443
2022-02-11 15:20:18,936 DEBUG urllib3.connectionpool MainThread : https://maps.googleapis.com:443 "GET /maps/api/geocode/json?address=401+Chapel+Dr%2C+Durham%2C+NC+27705&key=AIzaSyB0b7GWpLob05JP7aVeAt9iMjY0FjDv0_o HTTP/1.1" 200 None
2022-02-11 15:20:46,960 ERROR app ThreadPoolExecutor-0_0 : Exception on /current_user [GET]
Traceback (most recent call last):
  File "/usr/local/lib/python3.8/dist-packages/sqlalchemy/engine/base.py", line 1802, in _execute_context
    self.dialect.do_execute(
  File "/usr/local/lib/python3.8/dist-packages/sqlalchemy/engine/default.py", line 732, in do_execute
    cursor.execute(statement, parameters)
psycopg2.errors.UndefinedColumn: column students.name does not exist
LINE 1: SELECT students.id AS students_id, students.name AS students...
                                           ^


The above exception was the direct cause of the following exception:

Traceback (most recent call last):
  File "/usr/local/lib/python3.8/dist-packages/flask/app.py", line 2073, in wsgi_app
    response = self.full_dispatch_request()
  File "/usr/local/lib/python3.8/dist-packages/flask/app.py", line 1518, in full_dispatch_request
    rv = self.handle_user_exception(e)
  File "/usr/local/lib/python3.8/dist-packages/flask_cors/extension.py", line 165, in wrapped_function
    return cors_after_request(app.make_response(f(*args, **kwargs)))
  File "/usr/local/lib/python3.8/dist-packages/flask/app.py", line 1516, in full_dispatch_request
    rv = self.dispatch_request()
  File "/usr/local/lib/python3.8/dist-packages/flask/app.py", line 1502, in dispatch_request
    return self.ensure_sync(self.view_functions[rule.endpoint])(**req.view_args)
  File "/usr/local/lib/python3.8/dist-packages/flask_jwt_extended/view_decorators.py", line 127, in decorator
    return current_app.ensure_sync(fn)(*args, **kwargs)
  File "/usr/local/lib/python3.8/dist-packages/flask_cors/decorator.py", line 128, in wrapped_function
    resp = make_response(f(*args, **kwargs))
  File "/app/app.py", line 76, in get_current_user
    students = Student.query.filter_by(user_id = user.id).all()
  File "/usr/local/lib/python3.8/dist-packages/sqlalchemy/orm/query.py", line 2759, in all
    return self._iter().all()
  File "/usr/local/lib/python3.8/dist-packages/sqlalchemy/orm/query.py", line 2894, in _iter
    result = self.session.execute(
  File "/usr/local/lib/python3.8/dist-packages/sqlalchemy/orm/session.py", line 1692, in execute
    result = conn._execute_20(statement, params or {}, execution_options)
  File "/usr/local/lib/python3.8/dist-packages/sqlalchemy/engine/base.py", line 1614, in _execute_20
    return meth(self, args_10style, kwargs_10style, execution_options)
  File "/usr/local/lib/python3.8/dist-packages/sqlalchemy/sql/elements.py", line 325, in _execute_on_connection
    return connection._execute_clauseelement(
  File "/usr/local/lib/python3.8/dist-packages/sqlalchemy/engine/base.py", line 1481, in _execute_clauseelement
    ret = self._execute_context(
  File "/usr/local/lib/python3.8/dist-packages/sqlalchemy/engine/base.py", line 1845, in _execute_context
    self._handle_dbapi_exception(
  File "/usr/local/lib/python3.8/dist-packages/sqlalchemy/engine/base.py", line 2026, in _handle_dbapi_exception
    util.raise_(
  File "/usr/local/lib/python3.8/dist-packages/sqlalchemy/util/compat.py", line 207, in raise_
    raise exception
  File "/usr/local/lib/python3.8/dist-packages/sqlalchemy/engine/base.py", line 1802, in _execute_context
    self.dialect.do_execute(
  File "/usr/local/lib/python3.8/dist-packages/sqlalchemy/engine/default.py", line 732, in do_execute
    cursor.execute(statement, parameters)
sqlalchemy.exc.ProgrammingError: (psycopg2.errors.UndefinedColumn) column students.name does not exist
LINE 1: SELECT students.id AS students_id, students.name AS students...
                                           ^

[SQL: SELECT students.id AS students_id, students.name AS students_name, students.student_id AS students_student_id, students.school_id AS students_school_id, students.route_id AS students_route_id, students.user_id AS students_user_id 
FROM students 
WHERE students.user_id = %(user_id_1)s]
[parameters: {'user_id_1': 1}]
(Background on this error at: https://sqlalche.me/e/14/f405)
2022-02-11 15:20:54,123 ERROR app ThreadPoolExecutor-0_0 : Exception on /current_user [GET]
Traceback (most recent call last):
  File "/usr/local/lib/python3.8/dist-packages/sqlalchemy/engine/base.py", line 1802, in _execute_context
    self.dialect.do_execute(
  File "/usr/local/lib/python3.8/dist-packages/sqlalchemy/engine/default.py", line 732, in do_execute
    cursor.execute(statement, parameters)
psycopg2.errors.UndefinedColumn: column students.name does not exist
LINE 1: SELECT students.id AS students_id, students.name AS students...
                                           ^


The above exception was the direct cause of the following exception:

Traceback (most recent call last):
  File "/usr/local/lib/python3.8/dist-packages/flask/app.py", line 2073, in wsgi_app
    response = self.full_dispatch_request()
  File "/usr/local/lib/python3.8/dist-packages/flask/app.py", line 1518, in full_dispatch_request
    rv = self.handle_user_exception(e)
  File "/usr/local/lib/python3.8/dist-packages/flask_cors/extension.py", line 165, in wrapped_function
    return cors_after_request(app.make_response(f(*args, **kwargs)))
  File "/usr/local/lib/python3.8/dist-packages/flask/app.py", line 1516, in full_dispatch_request
    rv = self.dispatch_request()
  File "/usr/local/lib/python3.8/dist-packages/flask/app.py", line 1502, in dispatch_request
    return self.ensure_sync(self.view_functions[rule.endpoint])(**req.view_args)
  File "/usr/local/lib/python3.8/dist-packages/flask_jwt_extended/view_decorators.py", line 127, in decorator
    return current_app.ensure_sync(fn)(*args, **kwargs)
  File "/usr/local/lib/python3.8/dist-packages/flask_cors/decorator.py", line 128, in wrapped_function
    resp = make_response(f(*args, **kwargs))
  File "/app/app.py", line 76, in get_current_user
    students = Student.query.filter_by(user_id = user.id).all()
  File "/usr/local/lib/python3.8/dist-packages/sqlalchemy/orm/query.py", line 2759, in all
    return self._iter().all()
  File "/usr/local/lib/python3.8/dist-packages/sqlalchemy/orm/query.py", line 2894, in _iter
    result = self.session.execute(
  File "/usr/local/lib/python3.8/dist-packages/sqlalchemy/orm/session.py", line 1692, in execute
    result = conn._execute_20(statement, params or {}, execution_options)
  File "/usr/local/lib/python3.8/dist-packages/sqlalchemy/engine/base.py", line 1614, in _execute_20
    return meth(self, args_10style, kwargs_10style, execution_options)
  File "/usr/local/lib/python3.8/dist-packages/sqlalchemy/sql/elements.py", line 325, in _execute_on_connection
    return connection._execute_clauseelement(
  File "/usr/local/lib/python3.8/dist-packages/sqlalchemy/engine/base.py", line 1481, in _execute_clauseelement
    ret = self._execute_context(
  File "/usr/local/lib/python3.8/dist-packages/sqlalchemy/engine/base.py", line 1845, in _execute_context
    self._handle_dbapi_exception(
  File "/usr/local/lib/python3.8/dist-packages/sqlalchemy/engine/base.py", line 2026, in _handle_dbapi_exception
    util.raise_(
  File "/usr/local/lib/python3.8/dist-packages/sqlalchemy/util/compat.py", line 207, in raise_
    raise exception
  File "/usr/local/lib/python3.8/dist-packages/sqlalchemy/engine/base.py", line 1802, in _execute_context
    self.dialect.do_execute(
  File "/usr/local/lib/python3.8/dist-packages/sqlalchemy/engine/default.py", line 732, in do_execute
    cursor.execute(statement, parameters)
sqlalchemy.exc.ProgrammingError: (psycopg2.errors.UndefinedColumn) column students.name does not exist
LINE 1: SELECT students.id AS students_id, students.name AS students...
                                           ^

[SQL: SELECT students.id AS students_id, students.name AS students_name, students.student_id AS students_student_id, students.school_id AS students_school_id, students.route_id AS students_route_id, students.user_id AS students_user_id 
FROM students 
WHERE students.user_id = %(user_id_1)s]
[parameters: {'user_id_1': 1}]
(Background on this error at: https://sqlalche.me/e/14/f405)
2022-02-11 15:21:54,304 DEBUG urllib3.connectionpool MainThread : Starting new HTTPS connection (1): maps.googleapis.com:443
2022-02-11 15:21:54,567 DEBUG urllib3.connectionpool MainThread : https://maps.googleapis.com:443 "GET /maps/api/geocode/json?address=401+Chapel+Dr%2C+Durham%2C+NC+27705&key=AIzaSyB0b7GWpLob05JP7aVeAt9iMjY0FjDv0_o HTTP/1.1" 200 None
2022-02-11 15:22:13,634 DEBUG urllib3.connectionpool MainThread : Starting new HTTPS connection (1): maps.googleapis.com:443
2022-02-11 15:22:14,166 DEBUG urllib3.connectionpool MainThread : https://maps.googleapis.com:443 "GET /maps/api/geocode/json?address=11256+Palos+Verdes+Court%2C+Cupertino%2C+CA+95014&key=AIzaSyB0b7GWpLob05JP7aVeAt9iMjY0FjDv0_o HTTP/1.1" 200 None
2022-02-11 15:22:14,650 DEBUG urllib3.connectionpool MainThread : https://maps.googleapis.com:443 "GET /maps/api/geocode/json?address=14524+Lodestar+Drive%2C+Grass+Valley%2C+CA+95949&key=AIzaSyB0b7GWpLob05JP7aVeAt9iMjY0FjDv0_o HTTP/1.1" 200 None
2022-02-11 15:22:15,064 DEBUG urllib3.connectionpool MainThread : https://maps.googleapis.com:443 "GET /maps/api/geocode/json?address=4329+Howe+Street%2C+Oakland%2C+CA+94611&key=AIzaSyB0b7GWpLob05JP7aVeAt9iMjY0FjDv0_o HTTP/1.1" 200 None
2022-02-11 15:22:15,504 DEBUG urllib3.connectionpool MainThread : https://maps.googleapis.com:443 "GET /maps/api/geocode/json?address=11+Eclipse+Court%2C+Alameda%2C+CA+94501&key=AIzaSyB0b7GWpLob05JP7aVeAt9iMjY0FjDv0_o HTTP/1.1" 200 None
2022-02-11 15:22:15,811 DEBUG urllib3.connectionpool MainThread : https://maps.googleapis.com:443 "GET /maps/api/geocode/json?address=6420+Via+Baron%2C+Rancho+Palos+Verdes%2C+CA+90275&key=AIzaSyB0b7GWpLob05JP7aVeAt9iMjY0FjDv0_o HTTP/1.1" 200 None
2022-02-11 15:22:16,108 DEBUG urllib3.connectionpool MainThread : https://maps.googleapis.com:443 "GET /maps/api/geocode/json?address=5472+Sunstar+Common%2C+Fremont%2C+CA+94555&key=AIzaSyB0b7GWpLob05JP7aVeAt9iMjY0FjDv0_o HTTP/1.1" 200 None
2022-02-11 15:22:16,665 DEBUG urllib3.connectionpool MainThread : https://maps.googleapis.com:443 "GET /maps/api/geocode/json?address=5397+Wentworth+Avenue%2C+Oakland%2C+CA+94601&key=AIzaSyB0b7GWpLob05JP7aVeAt9iMjY0FjDv0_o HTTP/1.1" 200 None
2022-02-11 15:22:17,181 DEBUG urllib3.connectionpool MainThread : https://maps.googleapis.com:443 "GET /maps/api/geocode/json?address=2640+8th+Avenue%2C+Oakland%2C+CA+94606&key=AIzaSyB0b7GWpLob05JP7aVeAt9iMjY0FjDv0_o HTTP/1.1" 200 None
2022-02-11 15:22:17,595 DEBUG urllib3.connectionpool MainThread : https://maps.googleapis.com:443 "GET /maps/api/geocode/json?address=1870+A+Street%2C+Oroville%2C+CA+95966&key=AIzaSyB0b7GWpLob05JP7aVeAt9iMjY0FjDv0_o HTTP/1.1" 200 None
2022-02-11 15:22:18,000 DEBUG urllib3.connectionpool MainThread : https://maps.googleapis.com:443 "GET /maps/api/geocode/json?address=775+47th+Street%2C+Oakland%2C+CA+94609&key=AIzaSyB0b7GWpLob05JP7aVeAt9iMjY0FjDv0_o HTTP/1.1" 200 None
2022-02-11 15:22:18,409 DEBUG urllib3.connectionpool MainThread : https://maps.googleapis.com:443 "GET /maps/api/geocode/json?address=51035+Conifer+Drive%2C+Soda+Springs%2C+CA+95728&key=AIzaSyB0b7GWpLob05JP7aVeAt9iMjY0FjDv0_o HTTP/1.1" 200 None
2022-02-11 15:22:18,819 DEBUG urllib3.connectionpool MainThread : https://maps.googleapis.com:443 "GET /maps/api/geocode/json?address=450+C+Street%2C+Hayward%2C+CA+94541&key=AIzaSyB0b7GWpLob05JP7aVeAt9iMjY0FjDv0_o HTTP/1.1" 200 None
2022-02-11 15:22:19,232 DEBUG urllib3.connectionpool MainThread : https://maps.googleapis.com:443 "GET /maps/api/geocode/json?address=3827+West+Chapman+Avenue%2C+Orange%2C+CA+92868&key=AIzaSyB0b7GWpLob05JP7aVeAt9iMjY0FjDv0_o HTTP/1.1" 200 None
2022-02-11 15:22:19,641 DEBUG urllib3.connectionpool MainThread : https://maps.googleapis.com:443 "GET /maps/api/geocode/json?address=37600+Sycamore+Street%2C+Newark%2C+CA+94560&key=AIzaSyB0b7GWpLob05JP7aVeAt9iMjY0FjDv0_o HTTP/1.1" 200 None
2022-02-11 15:22:20,175 DEBUG urllib3.connectionpool MainThread : https://maps.googleapis.com:443 "GET /maps/api/geocode/json?address=4920+Quonset+Drive%2C+Sacramento%2C+CA+95820&key=AIzaSyB0b7GWpLob05JP7aVeAt9iMjY0FjDv0_o HTTP/1.1" 200 None
2022-02-11 15:22:20,534 DEBUG urllib3.connectionpool MainThread : https://maps.googleapis.com:443 "GET /maps/api/geocode/json?address=4500+Margalo+Avenue%2C+Bakersfield%2C+CA+93313&key=AIzaSyB0b7GWpLob05JP7aVeAt9iMjY0FjDv0_o HTTP/1.1" 200 None
2022-02-11 15:22:21,107 DEBUG urllib3.connectionpool MainThread : https://maps.googleapis.com:443 "GET /maps/api/geocode/json?address=7800+River+Mist+Avenue%2C+Bakersfield%2C+CA+93313&key=AIzaSyB0b7GWpLob05JP7aVeAt9iMjY0FjDv0_o HTTP/1.1" 200 None
2022-02-11 15:22:21,590 DEBUG urllib3.connectionpool MainThread : https://maps.googleapis.com:443 "GET /maps/api/geocode/json?address=21950+Arnold+Center+Road%2C+Carson%2C+CA+90810&key=AIzaSyB0b7GWpLob05JP7aVeAt9iMjY0FjDv0_o HTTP/1.1" 200 None
2022-02-11 15:22:22,048 DEBUG urllib3.connectionpool MainThread : https://maps.googleapis.com:443 "GET /maps/api/geocode/json?address=10202+Vista+Drive%2C+Cupertino%2C+CA+95014&key=AIzaSyB0b7GWpLob05JP7aVeAt9iMjY0FjDv0_o HTTP/1.1" 200 None
2022-02-11 15:22:22,219 DEBUG urllib3.connectionpool MainThread : https://maps.googleapis.com:443 "GET /maps/api/geocode/json?address=5397+Wentworth+Avenue%2C+Oakland%2C+CA+94601&key=AIzaSyB0b7GWpLob05JP7aVeAt9iMjY0FjDv0_o HTTP/1.1" 200 None
2022-02-11 15:22:22,597 DEBUG urllib3.connectionpool MainThread : https://maps.googleapis.com:443 "GET /maps/api/geocode/json?address=2708+Mabel+Street%2C+Berkeley%2C+CA+94702&key=AIzaSyB0b7GWpLob05JP7aVeAt9iMjY0FjDv0_o HTTP/1.1" 200 None
2022-02-11 15:22:22,959 DEBUG urllib3.connectionpool MainThread : https://maps.googleapis.com:443 "GET /maps/api/geocode/json?address=26466+Mockingbird+Lane%2C+Hayward%2C+CA+94544&key=AIzaSyB0b7GWpLob05JP7aVeAt9iMjY0FjDv0_o HTTP/1.1" 200 None
2022-02-11 15:22:23,332 DEBUG urllib3.connectionpool MainThread : https://maps.googleapis.com:443 "GET /maps/api/geocode/json?address=2443+Sierra+Nevada+Road%2C+Mammoth+Lakes%2C+CA+93546&key=AIzaSyB0b7GWpLob05JP7aVeAt9iMjY0FjDv0_o HTTP/1.1" 200 None
2022-02-11 15:22:23,716 DEBUG urllib3.connectionpool MainThread : https://maps.googleapis.com:443 "GET /maps/api/geocode/json?address=3027+Badger+Drive%2C+Pleasanton%2C+CA+94566&key=AIzaSyB0b7GWpLob05JP7aVeAt9iMjY0FjDv0_o HTTP/1.1" 200 None
2022-02-11 15:22:24,304 DEBUG urllib3.connectionpool MainThread : https://maps.googleapis.com:443 "GET /maps/api/geocode/json?address=1+Kelton+Court%2C+Oakland%2C+CA+94611&key=AIzaSyB0b7GWpLob05JP7aVeAt9iMjY0FjDv0_o HTTP/1.1" 200 None
2022-02-11 15:22:24,645 DEBUG urllib3.connectionpool MainThread : https://maps.googleapis.com:443 "GET /maps/api/geocode/json?address=649+Praderia+Circle%2C+Fremont%2C+CA+94539&key=AIzaSyB0b7GWpLob05JP7aVeAt9iMjY0FjDv0_o HTTP/1.1" 200 None
2022-02-11 15:22:24,955 DEBUG urllib3.connectionpool MainThread : https://maps.googleapis.com:443 "GET /maps/api/geocode/json?address=680+Quintana+Road%2C+Morro+Bay%2C+CA+93442&key=AIzaSyB0b7GWpLob05JP7aVeAt9iMjY0FjDv0_o HTTP/1.1" 200 None
2022-02-11 15:22:25,380 DEBUG urllib3.connectionpool MainThread : https://maps.googleapis.com:443 "GET /maps/api/geocode/json?address=2747+68th+Avenue%2C+Oakland%2C+CA+94605&key=AIzaSyB0b7GWpLob05JP7aVeAt9iMjY0FjDv0_o HTTP/1.1" 200 None
2022-02-11 15:22:25,726 DEBUG urllib3.connectionpool MainThread : https://maps.googleapis.com:443 "GET /maps/api/geocode/json?address=1234+Carmel+Street%2C+Madera%2C+CA+93638&key=AIzaSyB0b7GWpLob05JP7aVeAt9iMjY0FjDv0_o HTTP/1.1" 200 None
2022-02-11 15:22:26,015 DEBUG urllib3.connectionpool MainThread : https://maps.googleapis.com:443 "GET /maps/api/geocode/json?address=2755+Country+Drive%2C+Fremont%2C+CA+94536&key=AIzaSyB0b7GWpLob05JP7aVeAt9iMjY0FjDv0_o HTTP/1.1" 200 None
2022-02-11 15:22:26,427 DEBUG urllib3.connectionpool MainThread : https://maps.googleapis.com:443 "GET /maps/api/geocode/json?address=36360+Beech+Place%2C+Newark%2C+CA+94560&key=AIzaSyB0b7GWpLob05JP7aVeAt9iMjY0FjDv0_o HTTP/1.1" 200 None
2022-02-11 15:22:26,726 DEBUG urllib3.connectionpool MainThread : https://maps.googleapis.com:443 "GET /maps/api/geocode/json?address=514+Flower+Lane%2C+Alameda%2C+CA+94502&key=AIzaSyB0b7GWpLob05JP7aVeAt9iMjY0FjDv0_o HTTP/1.1" 200 None
2022-02-11 15:22:27,076 DEBUG urllib3.connectionpool MainThread : https://maps.googleapis.com:443 "GET /maps/api/geocode/json?address=1357+Addison+Street%2C+Berkeley%2C+CA+94702&key=AIzaSyB0b7GWpLob05JP7aVeAt9iMjY0FjDv0_o HTTP/1.1" 200 None
2022-02-11 15:22:27,395 DEBUG urllib3.connectionpool MainThread : https://maps.googleapis.com:443 "GET /maps/api/geocode/json?address=8934+Arrowrock+Trail%2C+Smartsville%2C+CA+95977&key=AIzaSyB0b7GWpLob05JP7aVeAt9iMjY0FjDv0_o HTTP/1.1" 200 None
2022-02-11 15:22:27,757 DEBUG urllib3.connectionpool MainThread : https://maps.googleapis.com:443 "GET /maps/api/geocode/json?address=2409+Park+Street%2C+Selma%2C+CA+93662&key=AIzaSyB0b7GWpLob05JP7aVeAt9iMjY0FjDv0_o HTTP/1.1" 200 None
2022-02-11 15:22:27,858 DEBUG urllib3.connectionpool MainThread : https://maps.googleapis.com:443 "GET /maps/api/geocode/json?address=4920+Quonset+Drive%2C+Sacramento%2C+CA+95820&key=AIzaSyB0b7GWpLob05JP7aVeAt9iMjY0FjDv0_o HTTP/1.1" 200 None
2022-02-11 15:22:28,354 DEBUG urllib3.connectionpool MainThread : https://maps.googleapis.com:443 "GET /maps/api/geocode/json?address=12091+Mierkey+Road%2C+Jackson%2C+CA+95642&key=AIzaSyB0b7GWpLob05JP7aVeAt9iMjY0FjDv0_o HTTP/1.1" 200 None
2022-02-11 15:22:28,791 DEBUG urllib3.connectionpool MainThread : https://maps.googleapis.com:443 "GET /maps/api/geocode/json?address=5725+Medallion+Court%2C+Castro+Valley%2C+CA+94552&key=AIzaSyB0b7GWpLob05JP7aVeAt9iMjY0FjDv0_o HTTP/1.1" 200 None
2022-02-11 15:22:29,174 DEBUG urllib3.connectionpool MainThread : https://maps.googleapis.com:443 "GET /maps/api/geocode/json?address=894+Windmill+Park+Lane%2C+Mountain+View%2C+CA+94043&key=AIzaSyB0b7GWpLob05JP7aVeAt9iMjY0FjDv0_o HTTP/1.1" 200 None
2022-02-11 15:22:29,584 DEBUG urllib3.connectionpool MainThread : https://maps.googleapis.com:443 "GET /maps/api/geocode/json?address=1300+Lemos+Lane%2C+Fremont%2C+CA+94539&key=AIzaSyB0b7GWpLob05JP7aVeAt9iMjY0FjDv0_o HTTP/1.1" 200 None
2022-02-11 15:22:57,815 ERROR app ThreadPoolExecutor-0_0 : Exception on /student [GET]
Traceback (most recent call last):
  File "/usr/local/lib/python3.8/dist-packages/flask/app.py", line 2073, in wsgi_app
    response = self.full_dispatch_request()
  File "/usr/local/lib/python3.8/dist-packages/flask/app.py", line 1518, in full_dispatch_request
    rv = self.handle_user_exception(e)
  File "/usr/local/lib/python3.8/dist-packages/flask_cors/extension.py", line 165, in wrapped_function
    return cors_after_request(app.make_response(f(*args, **kwargs)))
  File "/usr/local/lib/python3.8/dist-packages/flask/app.py", line 1516, in full_dispatch_request
    rv = self.dispatch_request()
  File "/usr/local/lib/python3.8/dist-packages/flask/app.py", line 1502, in dispatch_request
    return self.ensure_sync(self.view_functions[rule.endpoint])(**req.view_args)
  File "/usr/local/lib/python3.8/dist-packages/flask_cors/decorator.py", line 128, in wrapped_function
    resp = make_response(f(*args, **kwargs))
  File "/app/app.py", line 43, in decorator
    return fn(*args, **kwargs)
  File "/app/app.py", line 335, in students_get
    student_filt = StudentFilter(data={'name': name_search, 'student_id': id_search, 'order_by': sort, 'page': page}).paginate()
  File "/usr/local/lib/python3.8/dist-packages/sqlalchemy_filters/filters.py", line 527, in paginate
    return Paginator(query=self.apply(), page=page, page_size=page_size)
  File "/usr/local/lib/python3.8/dist-packages/sqlalchemy_filters/filters.py", line 539, in apply
    query = self.order_by(query)
  File "/usr/local/lib/python3.8/dist-packages/sqlalchemy_filters/filters.py", line 498, in order_by
    order_by = [
  File "/usr/local/lib/python3.8/dist-packages/sqlalchemy_filters/filters.py", line 499, in <listcomp>
    self._parse_order_by(ob)
  File "/usr/local/lib/python3.8/dist-packages/sqlalchemy_filters/filters.py", line 482, in _parse_order_by
    raise OrderByException(
sqlalchemy_filters.exceptions.OrderByException: Student does not have a field called 'full_name' to use in an ORDER BY clause.
2022-02-11 15:23:01,695 ERROR app ThreadPoolExecutor-0_0 : Exception on /student [GET]
Traceback (most recent call last):
  File "/usr/local/lib/python3.8/dist-packages/flask/app.py", line 2073, in wsgi_app
    response = self.full_dispatch_request()
  File "/usr/local/lib/python3.8/dist-packages/flask/app.py", line 1518, in full_dispatch_request
    rv = self.handle_user_exception(e)
  File "/usr/local/lib/python3.8/dist-packages/flask_cors/extension.py", line 165, in wrapped_function
    return cors_after_request(app.make_response(f(*args, **kwargs)))
  File "/usr/local/lib/python3.8/dist-packages/flask/app.py", line 1516, in full_dispatch_request
    rv = self.dispatch_request()
  File "/usr/local/lib/python3.8/dist-packages/flask/app.py", line 1502, in dispatch_request
    return self.ensure_sync(self.view_functions[rule.endpoint])(**req.view_args)
  File "/usr/local/lib/python3.8/dist-packages/flask_cors/decorator.py", line 128, in wrapped_function
    resp = make_response(f(*args, **kwargs))
  File "/app/app.py", line 43, in decorator
    return fn(*args, **kwargs)
  File "/app/app.py", line 335, in students_get
    student_filt = StudentFilter(data={'name': name_search, 'student_id': id_search, 'order_by': sort, 'page': page}).paginate()
  File "/usr/local/lib/python3.8/dist-packages/sqlalchemy_filters/filters.py", line 527, in paginate
    return Paginator(query=self.apply(), page=page, page_size=page_size)
  File "/usr/local/lib/python3.8/dist-packages/sqlalchemy_filters/filters.py", line 539, in apply
    query = self.order_by(query)
  File "/usr/local/lib/python3.8/dist-packages/sqlalchemy_filters/filters.py", line 498, in order_by
    order_by = [
  File "/usr/local/lib/python3.8/dist-packages/sqlalchemy_filters/filters.py", line 499, in <listcomp>
    self._parse_order_by(ob)
  File "/usr/local/lib/python3.8/dist-packages/sqlalchemy_filters/filters.py", line 482, in _parse_order_by
    raise OrderByException(
sqlalchemy_filters.exceptions.OrderByException: Student does not have a field called 'full_name' to use in an ORDER BY clause.
2022-02-11 15:23:05,068 ERROR app ThreadPoolExecutor-0_0 : Exception on /student [GET]
Traceback (most recent call last):
  File "/usr/local/lib/python3.8/dist-packages/flask/app.py", line 2073, in wsgi_app
    response = self.full_dispatch_request()
  File "/usr/local/lib/python3.8/dist-packages/flask/app.py", line 1518, in full_dispatch_request
    rv = self.handle_user_exception(e)
  File "/usr/local/lib/python3.8/dist-packages/flask_cors/extension.py", line 165, in wrapped_function
    return cors_after_request(app.make_response(f(*args, **kwargs)))
  File "/usr/local/lib/python3.8/dist-packages/flask/app.py", line 1516, in full_dispatch_request
    rv = self.dispatch_request()
  File "/usr/local/lib/python3.8/dist-packages/flask/app.py", line 1502, in dispatch_request
    return self.ensure_sync(self.view_functions[rule.endpoint])(**req.view_args)
  File "/usr/local/lib/python3.8/dist-packages/flask_cors/decorator.py", line 128, in wrapped_function
    resp = make_response(f(*args, **kwargs))
  File "/app/app.py", line 43, in decorator
    return fn(*args, **kwargs)
  File "/app/app.py", line 335, in students_get
    student_filt = StudentFilter(data={'name': name_search, 'student_id': id_search, 'order_by': sort, 'page': page}).paginate()
  File "/usr/local/lib/python3.8/dist-packages/sqlalchemy_filters/filters.py", line 527, in paginate
    return Paginator(query=self.apply(), page=page, page_size=page_size)
  File "/usr/local/lib/python3.8/dist-packages/sqlalchemy_filters/filters.py", line 539, in apply
    query = self.order_by(query)
  File "/usr/local/lib/python3.8/dist-packages/sqlalchemy_filters/filters.py", line 498, in order_by
    order_by = [
  File "/usr/local/lib/python3.8/dist-packages/sqlalchemy_filters/filters.py", line 499, in <listcomp>
    self._parse_order_by(ob)
  File "/usr/local/lib/python3.8/dist-packages/sqlalchemy_filters/filters.py", line 482, in _parse_order_by
    raise OrderByException(
sqlalchemy_filters.exceptions.OrderByException: Student does not have a field called 'full_name' to use in an ORDER BY clause.
2022-02-11 15:25:38,358 ERROR app ThreadPoolExecutor-0_0 : Exception on /student [GET]
Traceback (most recent call last):
  File "/usr/local/lib/python3.8/dist-packages/flask/app.py", line 2073, in wsgi_app
    response = self.full_dispatch_request()
  File "/usr/local/lib/python3.8/dist-packages/flask/app.py", line 1518, in full_dispatch_request
    rv = self.handle_user_exception(e)
  File "/usr/local/lib/python3.8/dist-packages/flask_cors/extension.py", line 165, in wrapped_function
    return cors_after_request(app.make_response(f(*args, **kwargs)))
  File "/usr/local/lib/python3.8/dist-packages/flask/app.py", line 1516, in full_dispatch_request
    rv = self.dispatch_request()
  File "/usr/local/lib/python3.8/dist-packages/flask/app.py", line 1502, in dispatch_request
    return self.ensure_sync(self.view_functions[rule.endpoint])(**req.view_args)
  File "/usr/local/lib/python3.8/dist-packages/flask_cors/decorator.py", line 128, in wrapped_function
    resp = make_response(f(*args, **kwargs))
  File "/app/app.py", line 43, in decorator
    return fn(*args, **kwargs)
  File "/app/app.py", line 335, in students_get
    student_filt = StudentFilter(data={'name': name_search, 'student_id': id_search, 'order_by': sort, 'page': page}).paginate()
  File "/usr/local/lib/python3.8/dist-packages/sqlalchemy_filters/filters.py", line 527, in paginate
    return Paginator(query=self.apply(), page=page, page_size=page_size)
  File "/usr/local/lib/python3.8/dist-packages/sqlalchemy_filters/filters.py", line 539, in apply
    query = self.order_by(query)
  File "/usr/local/lib/python3.8/dist-packages/sqlalchemy_filters/filters.py", line 498, in order_by
    order_by = [
  File "/usr/local/lib/python3.8/dist-packages/sqlalchemy_filters/filters.py", line 499, in <listcomp>
    self._parse_order_by(ob)
  File "/usr/local/lib/python3.8/dist-packages/sqlalchemy_filters/filters.py", line 482, in _parse_order_by
    raise OrderByException(
sqlalchemy_filters.exceptions.OrderByException: Student does not have a field called 'full_name' to use in an ORDER BY clause.
2022-02-11 15:25:39,408 ERROR app ThreadPoolExecutor-0_0 : Exception on /student [GET]
Traceback (most recent call last):
  File "/usr/local/lib/python3.8/dist-packages/flask/app.py", line 2073, in wsgi_app
    response = self.full_dispatch_request()
  File "/usr/local/lib/python3.8/dist-packages/flask/app.py", line 1518, in full_dispatch_request
    rv = self.handle_user_exception(e)
  File "/usr/local/lib/python3.8/dist-packages/flask_cors/extension.py", line 165, in wrapped_function
    return cors_after_request(app.make_response(f(*args, **kwargs)))
  File "/usr/local/lib/python3.8/dist-packages/flask/app.py", line 1516, in full_dispatch_request
    rv = self.dispatch_request()
  File "/usr/local/lib/python3.8/dist-packages/flask/app.py", line 1502, in dispatch_request
    return self.ensure_sync(self.view_functions[rule.endpoint])(**req.view_args)
  File "/usr/local/lib/python3.8/dist-packages/flask_cors/decorator.py", line 128, in wrapped_function
    resp = make_response(f(*args, **kwargs))
  File "/app/app.py", line 43, in decorator
    return fn(*args, **kwargs)
  File "/app/app.py", line 335, in students_get
    student_filt = StudentFilter(data={'name': name_search, 'student_id': id_search, 'order_by': sort, 'page': page}).paginate()
  File "/usr/local/lib/python3.8/dist-packages/sqlalchemy_filters/filters.py", line 527, in paginate
    return Paginator(query=self.apply(), page=page, page_size=page_size)
  File "/usr/local/lib/python3.8/dist-packages/sqlalchemy_filters/filters.py", line 539, in apply
    query = self.order_by(query)
  File "/usr/local/lib/python3.8/dist-packages/sqlalchemy_filters/filters.py", line 498, in order_by
    order_by = [
  File "/usr/local/lib/python3.8/dist-packages/sqlalchemy_filters/filters.py", line 499, in <listcomp>
    self._parse_order_by(ob)
  File "/usr/local/lib/python3.8/dist-packages/sqlalchemy_filters/filters.py", line 482, in _parse_order_by
    raise OrderByException(
sqlalchemy_filters.exceptions.OrderByException: Student does not have a field called 'full_name' to use in an ORDER BY clause.
2022-02-11 15:25:49,076 ERROR app ThreadPoolExecutor-0_0 : Exception on /student [GET]
Traceback (most recent call last):
  File "/usr/local/lib/python3.8/dist-packages/flask/app.py", line 2073, in wsgi_app
    response = self.full_dispatch_request()
  File "/usr/local/lib/python3.8/dist-packages/flask/app.py", line 1518, in full_dispatch_request
    rv = self.handle_user_exception(e)
  File "/usr/local/lib/python3.8/dist-packages/flask_cors/extension.py", line 165, in wrapped_function
    return cors_after_request(app.make_response(f(*args, **kwargs)))
  File "/usr/local/lib/python3.8/dist-packages/flask/app.py", line 1516, in full_dispatch_request
    rv = self.dispatch_request()
  File "/usr/local/lib/python3.8/dist-packages/flask/app.py", line 1502, in dispatch_request
    return self.ensure_sync(self.view_functions[rule.endpoint])(**req.view_args)
  File "/usr/local/lib/python3.8/dist-packages/flask_cors/decorator.py", line 128, in wrapped_function
    resp = make_response(f(*args, **kwargs))
  File "/app/app.py", line 43, in decorator
    return fn(*args, **kwargs)
  File "/app/app.py", line 335, in students_get
    student_filt = StudentFilter(data={'name': name_search, 'student_id': id_search, 'order_by': sort, 'page': page}).paginate()
  File "/usr/local/lib/python3.8/dist-packages/sqlalchemy_filters/filters.py", line 527, in paginate
    return Paginator(query=self.apply(), page=page, page_size=page_size)
  File "/usr/local/lib/python3.8/dist-packages/sqlalchemy_filters/filters.py", line 539, in apply
    query = self.order_by(query)
  File "/usr/local/lib/python3.8/dist-packages/sqlalchemy_filters/filters.py", line 498, in order_by
    order_by = [
  File "/usr/local/lib/python3.8/dist-packages/sqlalchemy_filters/filters.py", line 499, in <listcomp>
    self._parse_order_by(ob)
  File "/usr/local/lib/python3.8/dist-packages/sqlalchemy_filters/filters.py", line 482, in _parse_order_by
    raise OrderByException(
sqlalchemy_filters.exceptions.OrderByException: Student does not have a field called 'full_name' to use in an ORDER BY clause.
2022-02-11 15:41:38,870 DEBUG root ThreadPoolExecutor-0_0 : in here10
2022-02-11 15:41:38,895 DEBUG root ThreadPoolExecutor-0_0 : in here11
2022-02-11 15:42:43,130 ERROR app ThreadPoolExecutor-0_1 : Exception on /stop/1 [GET]
Traceback (most recent call last):
  File "/usr/local/lib/python3.8/dist-packages/flask/app.py", line 2073, in wsgi_app
    response = self.full_dispatch_request()
  File "/usr/local/lib/python3.8/dist-packages/flask/app.py", line 1518, in full_dispatch_request
    rv = self.handle_user_exception(e)
  File "/usr/local/lib/python3.8/dist-packages/flask_cors/extension.py", line 165, in wrapped_function
    return cors_after_request(app.make_response(f(*args, **kwargs)))
  File "/usr/local/lib/python3.8/dist-packages/flask/app.py", line 1516, in full_dispatch_request
    rv = self.dispatch_request()
  File "/usr/local/lib/python3.8/dist-packages/flask/app.py", line 1502, in dispatch_request
    return self.ensure_sync(self.view_functions[rule.endpoint])(**req.view_args)
  File "/usr/local/lib/python3.8/dist-packages/flask_cors/decorator.py", line 128, in wrapped_function
    resp = make_response(f(*args, **kwargs))
  File "/app/app.py", line 43, in decorator
    return fn(*args, **kwargs)
  File "/app/app.py", line 763, in stops_get
    return json.dumps({'success': True, 'stop': stop.as_dict()})
  File "/app/models.py", line 130, in as_dict
    main['latitude'] = datetime.strftime("%Y-%m-%dT%H:%M:%SZ", main['latitude'])
TypeError: descriptor 'strftime' for 'datetime.date' objects doesn't apply to a 'str' object
2022-02-11 15:44:43,964 ERROR app ThreadPoolExecutor-0_0 : Exception on /stop/1 [GET]
Traceback (most recent call last):
  File "/usr/local/lib/python3.8/dist-packages/flask/app.py", line 2073, in wsgi_app
    response = self.full_dispatch_request()
  File "/usr/local/lib/python3.8/dist-packages/flask/app.py", line 1518, in full_dispatch_request
    rv = self.handle_user_exception(e)
  File "/usr/local/lib/python3.8/dist-packages/flask_cors/extension.py", line 165, in wrapped_function
    return cors_after_request(app.make_response(f(*args, **kwargs)))
  File "/usr/local/lib/python3.8/dist-packages/flask/app.py", line 1516, in full_dispatch_request
    rv = self.dispatch_request()
  File "/usr/local/lib/python3.8/dist-packages/flask/app.py", line 1502, in dispatch_request
    return self.ensure_sync(self.view_functions[rule.endpoint])(**req.view_args)
  File "/usr/local/lib/python3.8/dist-packages/flask_cors/decorator.py", line 128, in wrapped_function
    resp = make_response(f(*args, **kwargs))
  File "/app/app.py", line 43, in decorator
    return fn(*args, **kwargs)
  File "/app/app.py", line 763, in stops_get
    return json.dumps({'success': True, 'stop': stop.as_dict()})
  File "/app/models.py", line 130, in as_dict
    main['pickup_time'] = datetime.strftime("%Y-%m-%dT%H:%M:%SZ", main['pickup_time'])
TypeError: descriptor 'strftime' for 'datetime.date' objects doesn't apply to a 'str' object
2022-02-11 15:45:18,966 ERROR app ThreadPoolExecutor-0_0 : Exception on /stop/1 [GET]
Traceback (most recent call last):
  File "/usr/local/lib/python3.8/dist-packages/flask/app.py", line 2073, in wsgi_app
    response = self.full_dispatch_request()
  File "/usr/local/lib/python3.8/dist-packages/flask/app.py", line 1518, in full_dispatch_request
    rv = self.handle_user_exception(e)
  File "/usr/local/lib/python3.8/dist-packages/flask_cors/extension.py", line 165, in wrapped_function
    return cors_after_request(app.make_response(f(*args, **kwargs)))
  File "/usr/local/lib/python3.8/dist-packages/flask/app.py", line 1516, in full_dispatch_request
    rv = self.dispatch_request()
  File "/usr/local/lib/python3.8/dist-packages/flask/app.py", line 1502, in dispatch_request
    return self.ensure_sync(self.view_functions[rule.endpoint])(**req.view_args)
  File "/usr/local/lib/python3.8/dist-packages/flask_cors/decorator.py", line 128, in wrapped_function
    resp = make_response(f(*args, **kwargs))
  File "/app/app.py", line 43, in decorator
    return fn(*args, **kwargs)
  File "/app/app.py", line 763, in stops_get
    return json.dumps({'success': True, 'stop': stop.as_dict()})
  File "/app/models.py", line 130, in as_dict
    main['pickup_time'] = datetime.strftime("%Y-%m-%dT%H:%M:%SZ", self.pickup_time)
TypeError: descriptor 'strftime' for 'datetime.date' objects doesn't apply to a 'str' object
2022-02-11 15:46:37,175 ERROR app ThreadPoolExecutor-0_0 : Exception on /stop/1 [GET]
Traceback (most recent call last):
  File "/usr/local/lib/python3.8/dist-packages/flask/app.py", line 2073, in wsgi_app
    response = self.full_dispatch_request()
  File "/usr/local/lib/python3.8/dist-packages/flask/app.py", line 1518, in full_dispatch_request
    rv = self.handle_user_exception(e)
  File "/usr/local/lib/python3.8/dist-packages/flask_cors/extension.py", line 165, in wrapped_function
    return cors_after_request(app.make_response(f(*args, **kwargs)))
  File "/usr/local/lib/python3.8/dist-packages/flask/app.py", line 1516, in full_dispatch_request
    rv = self.dispatch_request()
  File "/usr/local/lib/python3.8/dist-packages/flask/app.py", line 1502, in dispatch_request
    return self.ensure_sync(self.view_functions[rule.endpoint])(**req.view_args)
  File "/usr/local/lib/python3.8/dist-packages/flask_cors/decorator.py", line 128, in wrapped_function
    resp = make_response(f(*args, **kwargs))
  File "/app/app.py", line 43, in decorator
    return fn(*args, **kwargs)
  File "/app/app.py", line 763, in stops_get
    return json.dumps({'success': True, 'stop': stop.as_dict()})
  File "/app/models.py", line 130, in as_dict
    logging.debug(type(self.pickup_time))
NameError: name 'logging' is not defined
2022-02-11 15:47:23,696 DEBUG root ThreadPoolExecutor-0_0 : <class 'NoneType'>
2022-02-11 15:47:23,699 ERROR app ThreadPoolExecutor-0_0 : Exception on /stop/1 [GET]
Traceback (most recent call last):
  File "/usr/local/lib/python3.8/dist-packages/flask/app.py", line 2073, in wsgi_app
    response = self.full_dispatch_request()
  File "/usr/local/lib/python3.8/dist-packages/flask/app.py", line 1518, in full_dispatch_request
    rv = self.handle_user_exception(e)
  File "/usr/local/lib/python3.8/dist-packages/flask_cors/extension.py", line 165, in wrapped_function
    return cors_after_request(app.make_response(f(*args, **kwargs)))
  File "/usr/local/lib/python3.8/dist-packages/flask/app.py", line 1516, in full_dispatch_request
    rv = self.dispatch_request()
  File "/usr/local/lib/python3.8/dist-packages/flask/app.py", line 1502, in dispatch_request
    return self.ensure_sync(self.view_functions[rule.endpoint])(**req.view_args)
  File "/usr/local/lib/python3.8/dist-packages/flask_cors/decorator.py", line 128, in wrapped_function
    resp = make_response(f(*args, **kwargs))
  File "/app/app.py", line 43, in decorator
    return fn(*args, **kwargs)
  File "/app/app.py", line 763, in stops_get
    return json.dumps({'success': True, 'stop': stop.as_dict()})
  File "/app/models.py", line 135, in as_dict
    main['pickup_time'] = datetime.strftime("%Y-%m-%dT%H:%M:%SZ", self.pickup_time)
TypeError: descriptor 'strftime' for 'datetime.date' objects doesn't apply to a 'str' object
2022-02-11 15:49:20,270 DEBUG root ThreadPoolExecutor-0_0 : <class 'datetime.time'>
2022-02-11 15:49:20,272 ERROR app ThreadPoolExecutor-0_0 : Exception on /stop/3 [GET]
Traceback (most recent call last):
  File "/usr/local/lib/python3.8/dist-packages/flask/app.py", line 2073, in wsgi_app
    response = self.full_dispatch_request()
  File "/usr/local/lib/python3.8/dist-packages/flask/app.py", line 1518, in full_dispatch_request
    rv = self.handle_user_exception(e)
  File "/usr/local/lib/python3.8/dist-packages/flask_cors/extension.py", line 165, in wrapped_function
    return cors_after_request(app.make_response(f(*args, **kwargs)))
  File "/usr/local/lib/python3.8/dist-packages/flask/app.py", line 1516, in full_dispatch_request
    rv = self.dispatch_request()
  File "/usr/local/lib/python3.8/dist-packages/flask/app.py", line 1502, in dispatch_request
    return self.ensure_sync(self.view_functions[rule.endpoint])(**req.view_args)
  File "/usr/local/lib/python3.8/dist-packages/flask_cors/decorator.py", line 128, in wrapped_function
    resp = make_response(f(*args, **kwargs))
  File "/app/app.py", line 43, in decorator
    return fn(*args, **kwargs)
  File "/app/app.py", line 763, in stops_get
    return json.dumps({'success': True, 'stop': stop.as_dict()})
  File "/app/models.py", line 135, in as_dict
    main['pickup_time'] = datetime.strftime("%Y-%m-%dT%H:%M:%SZ", self.pickup_time)
TypeError: descriptor 'strftime' for 'datetime.date' objects doesn't apply to a 'str' object
2022-02-11 15:51:19,889 DEBUG root ThreadPoolExecutor-0_0 : <class 'datetime.time'>
